Workbook

Sheet Mastersheet
A1: WSUC_ID | B1: WSUC_Name | C1: Province | D1: District | E1: Municipality_Type | F1: Municipality_Name | G1: Wards_Covered | H1: Latitude | I1: Longitude | J1: Join_Key | K1: Business_Plan | L1: HH_Served | M1: Total_HH | N1: Coverage_Pct | O1: Coverage_Score | P1: Scheme_Type | Q1: Billed_Volume | R1: Population_Served | S1: Actual_LPCD | T1: Target_LPCD | U1: Adequacy_Score | V1: WQ_Testing | W1: WQ_EColi | X1: WQ_Arsenic | Y1: WQ_Score | Z1: Hours_of_Supply | AA1: Reliability_Score | AB1: NRW_Logbook | AC1: NRW_Flow_Measurement | AD1: NRW_Reservoir_Scale | AE1: NRW_Flow_Meters | AF1: NRW_DMA | AG1: NRW_Score | AH1: Expenditure | AI1: Income | AJ1: Operating_Ratio | AK1: OM_Score | AL1: Metered_Connections | AM1: Total_Connections | AN1: Metering_Pct | AO1: Metering_Score | AP1: Grievance_Logbook | AQ1: Grievance_Mechanism | AR1: Grievance_Score | AS1: SPI_Pct | AT1: OEI_Pct | AU1: Category_Number | AV1: Category_Level
A2: =Spatial!A2 -> 1 | B2: =Spatial!B2 -> Lubhu_WSUC | C2: =Spatial!C2 -> Bagmati | D2: =Spatial!D2 -> Lalitpur District, Nepal | E2: =Spatial!E2 -> Municipality | F2: =Spatial!F2 -> Mahalaxmi | G2: =IFERROR(Spatial!G2,"") -> 0 | H2: 27.6231 | I2: 85.3814 | J2: =F2&"_"&D2 -> Mahalaxmi_Lalitpur District, Nepal | K2: =IFERROR(IF(VLOOKUP(A2,'Service Coverage'!$A:$C,3,0)="","",VLOOKUP(A2,'Service Coverage'!$A:$C,3,0)),"") -> Yes | L2: =IFERROR(IF(VLOOKUP(A2,'Service Coverage'!$A:$D,4,0)="","",VLOOKUP(A2,'Service Coverage'!$A:$D,4,0)),"") -> 2065 | M2: =IFERROR(IF(VLOOKUP(A2,'Service Coverage'!$A:$E,5,0)="","",VLOOKUP(A2,'Service Coverage'!$A:$E,5,0)),"") | N2: =IFERROR(IF(VLOOKUP(A2,'Service Coverage'!$A:$F,6,0)="","",VLOOKUP(A2,'Service Coverage'!$A:$F,6,0)),"") | O2: =IFERROR(IF(VLOOKUP(A2,'Service Coverage'!$A:$G,7,0)="","",VLOOKUP(A2,'Service Coverage'!$A:$G,7,0)),"") | P2: =IFERROR(IF(VLOOKUP(A2,Adequacy!$A:$C,3,0)="","",VLOOKUP(A2,Adequacy!$A:$C,3,0)),"") | Q2: =IFERROR(IF(VLOOKUP(A2,Adequacy!$A:$D,4,0)="","",VLOOKUP(A2,Adequacy!$A:$D,4,0)),"") -> 1500 | R2: =IFERROR(IF(VLOOKUP(A2,Adequacy!$A:$E,5,0)="","",VLOOKUP(A2,Adequacy!$A:$E,5,0)),"") | S2: =IFERROR(IF(VLOOKUP(A2,Adequacy!$A:$G,7,0)="","",VLOOKUP(A2,Adequacy!$A:$G,7,0)),"") | T2: =IFERROR(IF(VLOOKUP(A2,Adequacy!$A:$H,8,0)="","",VLOOKUP(A2,Adequacy!$A:$H,8,0)),"") | U2: =IFERROR(IF(VLOOKUP(A2,Adequacy!$A:$J,10,0)="","",VLOOKUP(A2,Adequacy!$A:$J,10,0)),"") | V2: =IFERROR(IF(VLOOKUP(A2,'Water Quality Score'!$A:$C,3,0)="","",VLOOKUP(A2,'Water Quality Score'!$A:$C,3,0)),"") -> yes | W2: =IFERROR(IF(VLOOKUP(A2,'Water Quality Score'!$A:$D,4,0)="","",VLOOKUP(A2,'Water Quality Score'!$A:$D,4,0)),"") | X2: =IFERROR(IF(VLOOKUP(A2,'Water Quality Score'!$A:$E,5,0)="","",VLOOKUP(A2,'Water Quality Score'!$A:$E,5,0)),"") | Y2: =IFERROR(IF(VLOOKUP(A2,'Water Quality Score'!$A:$F,6,0)="","",VLOOKUP(A2,'Water Quality Score'!$A:$F,6,0)),"") -> 0.2 | Z2: =IFERROR(IF(VLOOKUP(A2,'Reliability score'!$A:$C,3,0)="","",VLOOKUP(A2,'Reliability score'!$A:$C,3,0)),"") -> 24 | AA2: =IFERROR(IF(VLOOKUP(A2,'Reliability score'!$A:$D,4,0)="","",VLOOKUP(A2,'Reliability score'!$A:$D,4,0)),"") -> 1 | AB2: =IFERROR(IF(VLOOKUP(A2,NRW!$A:$C,3,0)="","",VLOOKUP(A2,NRW!$A:$C,3,0)),"") | AC2: =IFERROR(IF(VLOOKUP(A2,NRW!$A:$D,4,0)="","",VLOOKUP(A2,NRW!$A:$D,4,0)),"") | AD2: =IFERROR(IF(VLOOKUP(A2,NRW!$A:$E,5,0)="","",VLOOKUP(A2,NRW!$A:$E,5,0)),"") | AE2: =IFERROR(IF(VLOOKUP(A2,NRW!$A:$F,6,0)="","",VLOOKUP(A2,NRW!$A:$F,6,0)),"") | AF2: =IFERROR(IF(VLOOKUP(A2,NRW!$A:$G,7,0)="","",VLOOKUP(A2,NRW!$A:$G,7,0)),"") | AG2: =IFERROR(IF(OR(VLOOKUP(A2,NRW!$A:$H,8,0)="",VLOOKUP(A2,NRW!$A:$H,8,0)=0),"",VLOOKUP(A2,NRW!$A:$H,8,0)),"") | AH2: =IFERROR(IF(VLOOKUP(A2,'O&M score'!$A:$D,4,0)="","",VLOOKUP(A2,'O&M score'!$A:$D,4,0)),"") -> 16234344 | AI2: =IFERROR(IF(VLOOKUP(A2,'O&M score'!$A:$E,5,0)="","",VLOOKUP(A2,'O&M score'!$A:$E,5,0)),"") -> 17077043 | AJ2: =IFERROR(IF(VLOOKUP(A2,'O&M score'!$A:$F,6,0)="","",VLOOKUP(A2,'O&M score'!$A:$F,6,0)),"") -> 0.95065311 | AK2: =IFERROR(IF(VLOOKUP(A2,'O&M score'!$A:$G,7,0)="","",VLOOKUP(A2,'O&M score'!$A:$G,7,0)),"") -> 0.49869378 | AL2: =IFERROR(IF(VLOOKUP(A2,'Metering Ratio Score'!$A:$C,3,0)="","",VLOOKUP(A2,'Metering Ratio Score'!$A:$C,3,0)),"") -> 2065 | AM2: =IFERROR(IF(VLOOKUP(A2,'Metering Ratio Score'!$A:$D,4,0)="","",VLOOKUP(A2,'Metering Ratio Score'!$A:$D,4,0)),"") | AN2: =IFERROR(IF(VLOOKUP(A2,'Metering Ratio Score'!$A:$E,5,0)="","",VLOOKUP(A2,'Metering Ratio Score'!$A:$E,5,0)),"") | AO2: =IFERROR(IF(VLOOKUP(A2,'Metering Ratio Score'!$A:$F,6,0)="","",VLOOKUP(A2,'Metering Ratio Score'!$A:$F,6,0)),"") | AP2: =IFERROR(IF(VLOOKUP(A2,'Grievance Addressal'!$A:$C,3,0)="","",VLOOKUP(A2,'Grievance Addressal'!$A:$C,3,0)),"") | AQ2: =IFERROR(IF(VLOOKUP(A2,'Grievance Addressal'!$A:$D,4,0)="","",VLOOKUP(A2,'Grievance Addressal'!$A:$D,4,0)),"") -> yes | AR2: =IFERROR(IF(VLOOKUP(A2,'Grievance Addressal'!$A:$E,5,0)="","",VLOOKUP(A2,'Grievance Addressal'!$A:$E,5,0)),"") | AS2: =IFERROR(IF(VLOOKUP(A2,Summary_Index!$A$5:$N$281,7,0)="","",VLOOKUP(A2,Summary_Index!$A$5:$N$281,7,0)),"") | AT2: =IFERROR(IF(VLOOKUP(A2,Summary_Index!$A$5:$N$281,12,0)="","",VLOOKUP(A2,Summary_Index!$A$5:$N$281,12,0)),"") | AU2: =IFERROR(IF(VLOOKUP(A2,Summary_Index!$A$5:$N$281,13,0)="","",VLOOKUP(A2,Summary_Index!$A$5:$N$281,13,0)),"") | AV2: =IFERROR(IF(VLOOKUP(A2,Summary_Index!$A$5:$N$281,14,0)="","",VLOOKUP(A2,Summary_Index!$A$5:$N$281,14,0)),"")
A3: =Spatial!A3 -> 2 | B3: =Spatial!B3 -> Shivalaya_WSUC | C3: =Spatial!C3 -> Gandaki | D3: =Spatial!D3 -> Parbat District | E3: =Spatial!E3 -> Municipality | F3: =Spatial!F3 -> Kusma | G3: =IFERROR(Spatial!G3,"") -> 4,5,6,7 | H3: 28.1735 | I3: 83.9847 | J3: =F3&"_"&D3 -> Kusma_Parbat District | K3: =IFERROR(IF(VLOOKUP(A3,'Service Coverage'!$A:$C,3,0)="","",VLOOKUP(A3,'Service Coverage'!$A:$C,3,0)),"") -> No | L3: =IFERROR(IF(VLOOKUP(A3,'Service Coverage'!$A:$D,4,0)="","",VLOOKUP(A3,'Service Coverage'!$A:$D,4,0)),"") -> 2700 | M3: =IFERROR(IF(VLOOKUP(A3,'Service Coverage'!$A:$E,5,0)="","",VLOOKUP(A3,'Service Coverage'!$A:$E,5,0)),"") -> 4500 | N3: =IFERROR(IF(VLOOKUP(A3,'Service Coverage'!$A:$F,6,0)="","",VLOOKUP(A3,'Service Coverage'!$A:$F,6,0)),"") -> 60 | O3: =IFERROR(IF(VLOOKUP(A3,'Service Coverage'!$A:$G,7,0)="","",VLOOKUP(A3,'Service Coverage'!$A:$G,7,0)),"") -> 0 | P3: =IFERROR(IF(VLOOKUP(A3,Adequacy!$A:$C,3,0)="","",VLOOKUP(A3,Adequacy!$A:$C,3,0)),"") -> Gravity | Q3: =IFERROR(IF(VLOOKUP(A3,Adequacy!$A:$D,4,0)="","",VLOOKUP(A3,Adequacy!$A:$D,4,0)),"") -> 2055 | R3: =IFERROR(IF(VLOOKUP(A3,Adequacy!$A:$E,5,0)="","",VLOOKUP(A3,Adequacy!$A:$E,5,0)),"") -> 15000 | S3: =IFERROR(IF(VLOOKUP(A3,Adequacy!$A:$G,7,0)="","",VLOOKUP(A3,Adequacy!$A:$G,7,0)),"") -> 4.5666667 | T3: =IFERROR(IF(VLOOKUP(A3,Adequacy!$A:$H,8,0)="","",VLOOKUP(A3,Adequacy!$A:$H,8,0)),"") -> 120 | U3: =IFERROR(IF(VLOOKUP(A3,Adequacy!$A:$J,10,0)="","",VLOOKUP(A3,Adequacy!$A:$J,10,0)),"") -> 0 | V3: =IFERROR(IF(VLOOKUP(A3,'Water Quality Score'!$A:$C,3,0)="","",VLOOKUP(A3,'Water Quality Score'!$A:$C,3,0)),"") -> yes | W3: =IFERROR(IF(VLOOKUP(A3,'Water Quality Score'!$A:$D,4,0)="","",VLOOKUP(A3,'Water Quality Score'!$A:$D,4,0)),"") -> Yes | X3: =IFERROR(IF(VLOOKUP(A3,'Water Quality Score'!$A:$E,5,0)="","",VLOOKUP(A3,'Water Quality Score'!$A:$E,5,0)),"") -> Yes | Y3: =IFERROR(IF(VLOOKUP(A3,'Water Quality Score'!$A:$F,6,0)="","",VLOOKUP(A3,'Water Quality Score'!$A:$F,6,0)),"") -> 1 | Z3: =IFERROR(IF(VLOOKUP(A3,'Reliability score'!$A:$C,3,0)="","",VLOOKUP(A3,'Reliability score'!$A:$C,3,0)),"") -> 4 | AA3: =IFERROR(IF(VLOOKUP(A3,'Reliability score'!$A:$D,4,0)="","",VLOOKUP(A3,'Reliability score'!$A:$D,4,0)),"") -> 0.52380952 | AB3: =IFERROR(IF(VLOOKUP(A3,NRW!$A:$C,3,0)="","",VLOOKUP(A3,NRW!$A:$C,3,0)),"") -> No | AC3: =IFERROR(IF(VLOOKUP(A3,NRW!$A:$D,4,0)="","",VLOOKUP(A3,NRW!$A:$D,4,0)),"") -> Yes | AD3: =IFERROR(IF(VLOOKUP(A3,NRW!$A:$E,5,0)="","",VLOOKUP(A3,NRW!$A:$E,5,0)),"") -> Yes | AE3: =IFERROR(IF(VLOOKUP(A3,NRW!$A:$F,6,0)="","",VLOOKUP(A3,NRW!$A:$F,6,0)),"") -> No | AF3: =IFERROR(IF(VLOOKUP(A3,NRW!$A:$G,7,0)="","",VLOOKUP(A3,NRW!$A:$G,7,0)),"") -> Yes | AG3: =IFERROR(IF(OR(VLOOKUP(A3,NRW!$A:$H,8,0)="",VLOOKUP(A3,NRW!$A:$H,8,0)=0),"",VLOOKUP(A3,NRW!$A:$H,8,0)),"") | AH3: =IFERROR(IF(VLOOKUP(A3,'O&M score'!$A:$D,4,0)="","",VLOOKUP(A3,'O&M score'!$A:$D,4,0)),"") -> 13727893 | AI3: =IFERROR(IF(VLOOKUP(A3,'O&M score'!$A:$E,5,0)="","",VLOOKUP(A3,'O&M score'!$A:$E,5,0)),"") -> 20770712 | AJ3: =IFERROR(IF(VLOOKUP(A3,'O&M score'!$A:$F,6,0)="","",VLOOKUP(A3,'O&M score'!$A:$F,6,0)),"") -> 0.66092549 | AK3: =IFERROR(IF(VLOOKUP(A3,'O&M score'!$A:$G,7,0)="","",VLOOKUP(A3,'O&M score'!$A:$G,7,0)),"") -> 1 | AL3: =IFERROR(IF(VLOOKUP(A3,'Metering Ratio Score'!$A:$C,3,0)="","",VLOOKUP(A3,'Metering Ratio Score'!$A:$C,3,0)),"") -> 2700 | AM3: =IFERROR(IF(VLOOKUP(A3,'Metering Ratio Score'!$A:$D,4,0)="","",VLOOKUP(A3,'Metering Ratio Score'!$A:$D,4,0)),"") -> 2750 | AN3: =IFERROR(IF(VLOOKUP(A3,'Metering Ratio Score'!$A:$E,5,0)="","",VLOOKUP(A3,'Metering Ratio Score'!$A:$E,5,0)),"") -> 98.181818 | AO3: =IFERROR(IF(VLOOKUP(A3,'Metering Ratio Score'!$A:$F,6,0)="","",VLOOKUP(A3,'Metering Ratio Score'!$A:$F,6,0)),"") -> 0.95454545 | AP3: =IFERROR(IF(VLOOKUP(A3,'Grievance Addressal'!$A:$C,3,0)="","",VLOOKUP(A3,'Grievance Addressal'!$A:$C,3,0)),"") -> No | AQ3: =IFERROR(IF(VLOOKUP(A3,'Grievance Addressal'!$A:$D,4,0)="","",VLOOKUP(A3,'Grievance Addressal'!$A:$D,4,0)),"") -> yes | AR3: =IFERROR(IF(VLOOKUP(A3,'Grievance Addressal'!$A:$E,5,0)="","",VLOOKUP(A3,'Grievance Addressal'!$A:$E,5,0)),"") -> 0 | AS3: =IFERROR(IF(VLOOKUP(A3,Summary_Index!$A$5:$N$281,7,0)="","",VLOOKUP(A3,Summary_Index!$A$5:$N$281,7,0)),"") -> 45.5 | AT3: =IFERROR(IF(VLOOKUP(A3,Summary_Index!$A$5:$N$281,12,0)="","",VLOOKUP(A3,Summary_Index!$A$5:$N$281,12,0)),"") -> 44.1 | AU3: =IFERROR(IF(VLOOKUP(A3,Summary_Index!$A$5:$N$281,13,0)="","",VLOOKUP(A3,Summary_Index!$A$5:$N$281,13,0)),"") -> 8 | AV3: =IFERROR(IF(VLOOKUP(A3,Summary_Index!$A$5:$N$281,14,0)="","",VLOOKUP(A3,Summary_Index!$A$5:$N$281,14,0)),"") -> 8. Poor — Functioning Level
A4: =Spatial!A4 -> 3 | B4: =Spatial!B4 -> Ratnanagar_WSUC | C4: =Spatial!C4 -> Bagmati | D4: =Spatial!D4 -> Chitwan District | E4: =Spatial!E4 -> Municipality | F4: =Spatial!F4 -> Ratnanagar | G4: =IFERROR(Spatial!G4,"") -> 1 ,2,3,4,5,6,7,8,9,10,11,12,13 | H4: 27.6092 | I4: 84.3444 | J4: =F4&"_"&D4 -> Ratnanagar_Chitwan District | K4: =IFERROR(IF(VLOOKUP(A4,'Service Coverage'!$A:$C,3,0)="","",VLOOKUP(A4,'Service Coverage'!$A:$C,3,0)),"") -> No | L4: =IFERROR(IF(VLOOKUP(A4,'Service Coverage'!$A:$D,4,0)="","",VLOOKUP(A4,'Service Coverage'!$A:$D,4,0)),"") -> 18000 | M4: =IFERROR(IF(VLOOKUP(A4,'Service Coverage'!$A:$E,5,0)="","",VLOOKUP(A4,'Service Coverage'!$A:$E,5,0)),"") | N4: =IFERROR(IF(VLOOKUP(A4,'Service Coverage'!$A:$F,6,0)="","",VLOOKUP(A4,'Service Coverage'!$A:$F,6,0)),"") | O4: =IFERROR(IF(VLOOKUP(A4,'Service Coverage'!$A:$G,7,0)="","",VLOOKUP(A4,'Service Coverage'!$A:$G,7,0)),"") | P4: =IFERROR(IF(VLOOKUP(A4,Adequacy!$A:$C,3,0)="","",VLOOKUP(A4,Adequacy!$A:$C,3,0)),"") | Q4: =IFERROR(IF(VLOOKUP(A4,Adequacy!$A:$D,4,0)="","",VLOOKUP(A4,Adequacy!$A:$D,4,0)),"") -> 12500 | R4: =IFERROR(IF(VLOOKUP(A4,Adequacy!$A:$E,5,0)="","",VLOOKUP(A4,Adequacy!$A:$E,5,0)),"") -> 90000 | S4: =IFERROR(IF(VLOOKUP(A4,Adequacy!$A:$G,7,0)="","",VLOOKUP(A4,Adequacy!$A:$G,7,0)),"") -> 4.6296296 | T4: =IFERROR(IF(VLOOKUP(A4,Adequacy!$A:$H,8,0)="","",VLOOKUP(A4,Adequacy!$A:$H,8,0)),"") | U4: =IFERROR(IF(VLOOKUP(A4,Adequacy!$A:$J,10,0)="","",VLOOKUP(A4,Adequacy!$A:$J,10,0)),"") | V4: =IFERROR(IF(VLOOKUP(A4,'Water Quality Score'!$A:$C,3,0)="","",VLOOKUP(A4,'Water Quality Score'!$A:$C,3,0)),"") -> yes | W4: =IFERROR(IF(VLOOKUP(A4,'Water Quality Score'!$A:$D,4,0)="","",VLOOKUP(A4,'Water Quality Score'!$A:$D,4,0)),"") | X4: =IFERROR(IF(VLOOKUP(A4,'Water Quality Score'!$A:$E,5,0)="","",VLOOKUP(A4,'Water Quality Score'!$A:$E,5,0)),"") | Y4: =IFERROR(IF(VLOOKUP(A4,'Water Quality Score'!$A:$F,6,0)="","",VLOOKUP(A4,'Water Quality Score'!$A:$F,6,0)),"") -> 0.2 | Z4: =IFERROR(IF(VLOOKUP(A4,'Reliability score'!$A:$C,3,0)="","",VLOOKUP(A4,'Reliability score'!$A:$C,3,0)),"") -> 24 | AA4: =IFERROR(IF(VLOOKUP(A4,'Reliability score'!$A:$D,4,0)="","",VLOOKUP(A4,'Reliability score'!$A:$D,4,0)),"") -> 1 | AB4: =IFERROR(IF(VLOOKUP(A4,NRW!$A:$C,3,0)="","",VLOOKUP(A4,NRW!$A:$C,3,0)),"") | AC4: =IFERROR(IF(VLOOKUP(A4,NRW!$A:$D,4,0)="","",VLOOKUP(A4,NRW!$A:$D,4,0)),"") | AD4: =IFERROR(IF(VLOOKUP(A4,NRW!$A:$E,5,0)="","",VLOOKUP(A4,NRW!$A:$E,5,0)),"") | AE4: =IFERROR(IF(VLOOKUP(A4,NRW!$A:$F,6,0)="","",VLOOKUP(A4,NRW!$A:$F,6,0)),"") | AF4: =IFERROR(IF(VLOOKUP(A4,NRW!$A:$G,7,0)="","",VLOOKUP(A4,NRW!$A:$G,7,0)),"") | AG4: =IFERROR(IF(OR(VLOOKUP(A4,NRW!$A:$H,8,0)="",VLOOKUP(A4,NRW!$A:$H,8,0)=0),"",VLOOKUP(A4,NRW!$A:$H,8,0)),"") | AH4: =IFERROR(IF(VLOOKUP(A4,'O&M score'!$A:$D,4,0)="","",VLOOKUP(A4,'O&M score'!$A:$D,4,0)),"") -> 30000 | AI4: =IFERROR(IF(VLOOKUP(A4,'O&M score'!$A:$E,5,0)="","",VLOOKUP(A4,'O&M score'!$A:$E,5,0)),"") -> 40000 | AJ4: =IFERROR(IF(VLOOKUP(A4,'O&M score'!$A:$F,6,0)="","",VLOOKUP(A4,'O&M score'!$A:$F,6,0)),"") -> 0.75 | AK4: =IFERROR(IF(VLOOKUP(A4,'O&M score'!$A:$G,7,0)="","",VLOOKUP(A4,'O&M score'!$A:$G,7,0)),"") -> 0.9 | AL4: =IFERROR(IF(VLOOKUP(A4,'Metering Ratio Score'!$A:$C,3,0)="","",VLOOKUP(A4,'Metering Ratio Score'!$A:$C,3,0)),"") -> 15016 | AM4: =IFERROR(IF(VLOOKUP(A4,'Metering Ratio Score'!$A:$D,4,0)="","",VLOOKUP(A4,'Metering Ratio Score'!$A:$D,4,0)),"") | AN4: =IFERROR(IF(VLOOKUP(A4,'Metering Ratio Score'!$A:$E,5,0)="","",VLOOKUP(A4,'Metering Ratio Score'!$A:$E,5,0)),"") | AO4: =IFERROR(IF(VLOOKUP(A4,'Metering Ratio Score'!$A:$F,6,0)="","",VLOOKUP(A4,'Metering Ratio Score'!$A:$F,6,0)),"") | AP4: =IFERROR(IF(VLOOKUP(A4,'Grievance Addressal'!$A:$C,3,0)="","",VLOOKUP(A4,'Grievance Addressal'!$A:$C,3,0)),"") | AQ4: =IFERROR(IF(VLOOKUP(A4,'Grievance Addressal'!$A:$D,4,0)="","",VLOOKUP(A4,'Grievance Addressal'!$A:$D,4,0)),"") -> yes | AR4: =IFERROR(IF(VLOOKUP(A4,'Grievance Addressal'!$A:$E,5,0)="","",VLOOKUP(A4,'Grievance Addressal'!$A:$E,5,0)),"") | AS4: =IFERROR(IF(VLOOKUP(A4,Summary_Index!$A$5:$N$281,7,0)="","",VLOOKUP(A4,Summary_Index!$A$5:$N$281,7,0)),"") | AT4: =IFERROR(IF(VLOOKUP(A4,Summary_Index!$A$5:$N$281,12,0)="","",VLOOKUP(A4,Summary_Index!$A$5:$N$281,12,0)),"") | AU4: =IFERROR(IF(VLOOKUP(A4,Summary_Index!$A$5:$N$281,13,0)="","",VLOOKUP(A4,Summary_Index!$A$5:$N$281,13,0)),"") | AV4: =IFERROR(IF(VLOOKUP(A4,Summary_Index!$A$5:$N$281,14,0)="","",VLOOKUP(A4,Summary_Index!$A$5:$N$281,14,0)),"")
A5: =Spatial!A5 -> 4 | B5: =Spatial!B5 -> Nirmalpokhari_WSUC | C5: =Spatial!C5 -> Gandaki | D5: =Spatial!D5 -> Kaski District | E5: =Spatial!E5 -> Metropolitan | F5: =Spatial!F5 -> Pokhara | G5: =IFERROR(Spatial!G5,"") -> 0 | H5: 28.2096 | I5: 83.9856 | J5: =F5&"_"&D5 -> Pokhara_Kaski District | K5: =IFERROR(IF(VLOOKUP(A5,'Service Coverage'!$A:$C,3,0)="","",VLOOKUP(A5,'Service Coverage'!$A:$C,3,0)),"") -> Yes | L5: =IFERROR(IF(VLOOKUP(A5,'Service Coverage'!$A:$D,4,0)="","",VLOOKUP(A5,'Service Coverage'!$A:$D,4,0)),"") -> 2100 | M5: =IFERROR(IF(VLOOKUP(A5,'Service Coverage'!$A:$E,5,0)="","",VLOOKUP(A5,'Service Coverage'!$A:$E,5,0)),"") -> 3500 | N5: =IFERROR(IF(VLOOKUP(A5,'Service Coverage'!$A:$F,6,0)="","",VLOOKUP(A5,'Service Coverage'!$A:$F,6,0)),"") -> 60 | O5: =IFERROR(IF(VLOOKUP(A5,'Service Coverage'!$A:$G,7,0)="","",VLOOKUP(A5,'Service Coverage'!$A:$G,7,0)),"") -> 0 | P5: =IFERROR(IF(VLOOKUP(A5,Adequacy!$A:$C,3,0)="","",VLOOKUP(A5,Adequacy!$A:$C,3,0)),"") -> Pumped | Q5: =IFERROR(IF(VLOOKUP(A5,Adequacy!$A:$D,4,0)="","",VLOOKUP(A5,Adequacy!$A:$D,4,0)),"") -> 437 | R5: =IFERROR(IF(VLOOKUP(A5,Adequacy!$A:$E,5,0)="","",VLOOKUP(A5,Adequacy!$A:$E,5,0)),"") -> 11000 | S5: =IFERROR(IF(VLOOKUP(A5,Adequacy!$A:$G,7,0)="","",VLOOKUP(A5,Adequacy!$A:$G,7,0)),"") -> 1.3242424 | T5: =IFERROR(IF(VLOOKUP(A5,Adequacy!$A:$H,8,0)="","",VLOOKUP(A5,Adequacy!$A:$H,8,0)),"") -> 100 | U5: =IFERROR(IF(VLOOKUP(A5,Adequacy!$A:$J,10,0)="","",VLOOKUP(A5,Adequacy!$A:$J,10,0)),"") -> 0 | V5: =IFERROR(IF(VLOOKUP(A5,'Water Quality Score'!$A:$C,3,0)="","",VLOOKUP(A5,'Water Quality Score'!$A:$C,3,0)),"") -> yes | W5: =IFERROR(IF(VLOOKUP(A5,'Water Quality Score'!$A:$D,4,0)="","",VLOOKUP(A5,'Water Quality Score'!$A:$D,4,0)),"") -> Yes | X5: =IFERROR(IF(VLOOKUP(A5,'Water Quality Score'!$A:$E,5,0)="","",VLOOKUP(A5,'Water Quality Score'!$A:$E,5,0)),"") | Y5: =IFERROR(IF(VLOOKUP(A5,'Water Quality Score'!$A:$F,6,0)="","",VLOOKUP(A5,'Water Quality Score'!$A:$F,6,0)),"") -> 0.6 | Z5: =IFERROR(IF(VLOOKUP(A5,'Reliability score'!$A:$C,3,0)="","",VLOOKUP(A5,'Reliability score'!$A:$C,3,0)),"") -> 8 | AA5: =IFERROR(IF(VLOOKUP(A5,'Reliability score'!$A:$D,4,0)="","",VLOOKUP(A5,'Reliability score'!$A:$D,4,0)),"") -> 0.61904762 | AB5: =IFERROR(IF(VLOOKUP(A5,NRW!$A:$C,3,0)="","",VLOOKUP(A5,NRW!$A:$C,3,0)),"") -> No | AC5: =IFERROR(IF(VLOOKUP(A5,NRW!$A:$D,4,0)="","",VLOOKUP(A5,NRW!$A:$D,4,0)),"") -> Yes | AD5: =IFERROR(IF(VLOOKUP(A5,NRW!$A:$E,5,0)="","",VLOOKUP(A5,NRW!$A:$E,5,0)),"") -> Yes | AE5: =IFERROR(IF(VLOOKUP(A5,NRW!$A:$F,6,0)="","",VLOOKUP(A5,NRW!$A:$F,6,0)),"") -> Yes | AF5: =IFERROR(IF(VLOOKUP(A5,NRW!$A:$G,7,0)="","",VLOOKUP(A5,NRW!$A:$G,7,0)),"") -> Yes | AG5: =IFERROR(IF(OR(VLOOKUP(A5,NRW!$A:$H,8,0)="",VLOOKUP(A5,NRW!$A:$H,8,0)=0),"",VLOOKUP(A5,NRW!$A:$H,8,0)),"") | AH5: =IFERROR(IF(VLOOKUP(A5,'O&M score'!$A:$D,4,0)="","",VLOOKUP(A5,'O&M score'!$A:$D,4,0)),"") -> 2942620 | AI5: =IFERROR(IF(VLOOKUP(A5,'O&M score'!$A:$E,5,0)="","",VLOOKUP(A5,'O&M score'!$A:$E,5,0)),"") -> 9993660 | AJ5: =IFERROR(IF(VLOOKUP(A5,'O&M score'!$A:$F,6,0)="","",VLOOKUP(A5,'O&M score'!$A:$F,6,0)),"") -> 0.29444868 | AK5: =IFERROR(IF(VLOOKUP(A5,'O&M score'!$A:$G,7,0)="","",VLOOKUP(A5,'O&M score'!$A:$G,7,0)),"") -> 1 | AL5: =IFERROR(IF(VLOOKUP(A5,'Metering Ratio Score'!$A:$C,3,0)="","",VLOOKUP(A5,'Metering Ratio Score'!$A:$C,3,0)),"") -> 1300 | AM5: =IFERROR(IF(VLOOKUP(A5,'Metering Ratio Score'!$A:$D,4,0)="","",VLOOKUP(A5,'Metering Ratio Score'!$A:$D,4,0)),"") -> 2100 | AN5: =IFERROR(IF(VLOOKUP(A5,'Metering Ratio Score'!$A:$E,5,0)="","",VLOOKUP(A5,'Metering Ratio Score'!$A:$E,5,0)),"") -> 61.904762 | AO5: =IFERROR(IF(VLOOKUP(A5,'Metering Ratio Score'!$A:$F,6,0)="","",VLOOKUP(A5,'Metering Ratio Score'!$A:$F,6,0)),"") -> 0.047619048 | AP5: =IFERROR(IF(VLOOKUP(A5,'Grievance Addressal'!$A:$C,3,0)="","",VLOOKUP(A5,'Grievance Addressal'!$A:$C,3,0)),"") -> Yes | AQ5: =IFERROR(IF(VLOOKUP(A5,'Grievance Addressal'!$A:$D,4,0)="","",VLOOKUP(A5,'Grievance Addressal'!$A:$D,4,0)),"") -> yes | AR5: =IFERROR(IF(VLOOKUP(A5,'Grievance Addressal'!$A:$E,5,0)="","",VLOOKUP(A5,'Grievance Addressal'!$A:$E,5,0)),"") -> 1 | AS5: =IFERROR(IF(VLOOKUP(A5,Summary_Index!$A$5:$N$281,7,0)="","",VLOOKUP(A5,Summary_Index!$A$5:$N$281,7,0)),"") -> 33.4 | AT5: =IFERROR(IF(VLOOKUP(A5,Summary_Index!$A$5:$N$281,12,0)="","",VLOOKUP(A5,Summary_Index!$A$5:$N$281,12,0)),"") -> 51 | AU5: =IFERROR(IF(VLOOKUP(A5,Summary_Index!$A$5:$N$281,13,0)="","",VLOOKUP(A5,Summary_Index!$A$5:$N$281,13,0)),"") -> 6 | AV5: =IFERROR(IF(VLOOKUP(A5,Summary_Index!$A$5:$N$281,14,0)="","",VLOOKUP(A5,Summary_Index!$A$5:$N$281,14,0)),"") -> 6. Active — Functioning Level
A6: =Spatial!A6 -> 5 | B6: =Spatial!B6 -> Bhimad_WSUC | C6: =Spatial!C6 -> Gandaki | D6: =Spatial!D6 -> Tanahun District | E6: =Spatial!E6 -> Municipality | F6: =Spatial!F6 -> Bhimad | G6: =IFERROR(Spatial!G6,"") -> 0 | H6: 27.9667 | I6: 84.4167 | J6: =F6&"_"&D6 -> Bhimad_Tanahun District | K6: =IFERROR(IF(VLOOKUP(A6,'Service Coverage'!$A:$C,3,0)="","",VLOOKUP(A6,'Service Coverage'!$A:$C,3,0)),"") | L6: =IFERROR(IF(VLOOKUP(A6,'Service Coverage'!$A:$D,4,0)="","",VLOOKUP(A6,'Service Coverage'!$A:$D,4,0)),"") -> 2000 | M6: =IFERROR(IF(VLOOKUP(A6,'Service Coverage'!$A:$E,5,0)="","",VLOOKUP(A6,'Service Coverage'!$A:$E,5,0)),"") | N6: =IFERROR(IF(VLOOKUP(A6,'Service Coverage'!$A:$F,6,0)="","",VLOOKUP(A6,'Service Coverage'!$A:$F,6,0)),"") | O6: =IFERROR(IF(VLOOKUP(A6,'Service Coverage'!$A:$G,7,0)="","",VLOOKUP(A6,'Service Coverage'!$A:$G,7,0)),"") | P6: =IFERROR(IF(VLOOKUP(A6,Adequacy!$A:$C,3,0)="","",VLOOKUP(A6,Adequacy!$A:$C,3,0)),"") | Q6: =IFERROR(IF(VLOOKUP(A6,Adequacy!$A:$D,4,0)="","",VLOOKUP(A6,Adequacy!$A:$D,4,0)),"") -> 1220 | R6: =IFERROR(IF(VLOOKUP(A6,Adequacy!$A:$E,5,0)="","",VLOOKUP(A6,Adequacy!$A:$E,5,0)),"") | S6: =IFERROR(IF(VLOOKUP(A6,Adequacy!$A:$G,7,0)="","",VLOOKUP(A6,Adequacy!$A:$G,7,0)),"") | T6: =IFERROR(IF(VLOOKUP(A6,Adequacy!$A:$H,8,0)="","",VLOOKUP(A6,Adequacy!$A:$H,8,0)),"") | U6: =IFERROR(IF(VLOOKUP(A6,Adequacy!$A:$J,10,0)="","",VLOOKUP(A6,Adequacy!$A:$J,10,0)),"") | V6: =IFERROR(IF(VLOOKUP(A6,'Water Quality Score'!$A:$C,3,0)="","",VLOOKUP(A6,'Water Quality Score'!$A:$C,3,0)),"") -> yes | W6: =IFERROR(IF(VLOOKUP(A6,'Water Quality Score'!$A:$D,4,0)="","",VLOOKUP(A6,'Water Quality Score'!$A:$D,4,0)),"") | X6: =IFERROR(IF(VLOOKUP(A6,'Water Quality Score'!$A:$E,5,0)="","",VLOOKUP(A6,'Water Quality Score'!$A:$E,5,0)),"") | Y6: =IFERROR(IF(VLOOKUP(A6,'Water Quality Score'!$A:$F,6,0)="","",VLOOKUP(A6,'Water Quality Score'!$A:$F,6,0)),"") -> 0.2 | Z6: =IFERROR(IF(VLOOKUP(A6,'Reliability score'!$A:$C,3,0)="","",VLOOKUP(A6,'Reliability score'!$A:$C,3,0)),"") -> 12 | AA6: =IFERROR(IF(VLOOKUP(A6,'Reliability score'!$A:$D,4,0)="","",VLOOKUP(A6,'Reliability score'!$A:$D,4,0)),"") -> 0.71428571 | AB6: =IFERROR(IF(VLOOKUP(A6,NRW!$A:$C,3,0)="","",VLOOKUP(A6,NRW!$A:$C,3,0)),"") | AC6: =IFERROR(IF(VLOOKUP(A6,NRW!$A:$D,4,0)="","",VLOOKUP(A6,NRW!$A:$D,4,0)),"") | AD6: =IFERROR(IF(VLOOKUP(A6,NRW!$A:$E,5,0)="","",VLOOKUP(A6,NRW!$A:$E,5,0)),"") | AE6: =IFERROR(IF(VLOOKUP(A6,NRW!$A:$F,6,0)="","",VLOOKUP(A6,NRW!$A:$F,6,0)),"") | AF6: =IFERROR(IF(VLOOKUP(A6,NRW!$A:$G,7,0)="","",VLOOKUP(A6,NRW!$A:$G,7,0)),"") | AG6: =IFERROR(IF(OR(VLOOKUP(A6,NRW!$A:$H,8,0)="",VLOOKUP(A6,NRW!$A:$H,8,0)=0),"",VLOOKUP(A6,NRW!$A:$H,8,0)),"") | AH6: =IFERROR(IF(VLOOKUP(A6,'O&M score'!$A:$D,4,0)="","",VLOOKUP(A6,'O&M score'!$A:$D,4,0)),"") | AI6: =IFERROR(IF(VLOOKUP(A6,'O&M score'!$A:$E,5,0)="","",VLOOKUP(A6,'O&M score'!$A:$E,5,0)),"") | AJ6: =IFERROR(IF(VLOOKUP(A6,'O&M score'!$A:$F,6,0)="","",VLOOKUP(A6,'O&M score'!$A:$F,6,0)),"") | AK6: =IFERROR(IF(VLOOKUP(A6,'O&M score'!$A:$G,7,0)="","",VLOOKUP(A6,'O&M score'!$A:$G,7,0)),"") | AL6: =IFERROR(IF(VLOOKUP(A6,'Metering Ratio Score'!$A:$C,3,0)="","",VLOOKUP(A6,'Metering Ratio Score'!$A:$C,3,0)),"") | AM6: =IFERROR(IF(VLOOKUP(A6,'Metering Ratio Score'!$A:$D,4,0)="","",VLOOKUP(A6,'Metering Ratio Score'!$A:$D,4,0)),"") | AN6: =IFERROR(IF(VLOOKUP(A6,'Metering Ratio Score'!$A:$E,5,0)="","",VLOOKUP(A6,'Metering Ratio Score'!$A:$E,5,0)),"") | AO6: =IFERROR(IF(VLOOKUP(A6,'Metering Ratio Score'!$A:$F,6,0)="","",VLOOKUP(A6,'Metering Ratio Score'!$A:$F,6,0)),"") | AP6: =IFERROR(IF(VLOOKUP(A6,'Grievance Addressal'!$A:$C,3,0)="","",VLOOKUP(A6,'Grievance Addressal'!$A:$C,3,0)),"") | AQ6: =IFERROR(IF(VLOOKUP(A6,'Grievance Addressal'!$A:$D,4,0)="","",VLOOKUP(A6,'Grievance Addressal'!$A:$D,4,0)),"") -> yes | AR6: =IFERROR(IF(VLOOKUP(A6,'Grievance Addressal'!$A:$E,5,0)="","",VLOOKUP(A6,'Grievance Addressal'!$A:$E,5,0)),"") | AS6: =IFERROR(IF(VLOOKUP(A6,Summary_Index!$A$5:$N$281,7,0)="","",VLOOKUP(A6,Summary_Index!$A$5:$N$281,7,0)),"") | AT6: =IFERROR(IF(VLOOKUP(A6,Summary_Index!$A$5:$N$281,12,0)="","",VLOOKUP(A6,Summary_Index!$A$5:$N$281,12,0)),"") | AU6: =IFERROR(IF(VLOOKUP(A6,Summary_Index!$A$5:$N$281,13,0)="","",VLOOKUP(A6,Summary_Index!$A$5:$N$281,13,0)),"") | AV6: =IFERROR(IF(VLOOKUP(A6,Summary_Index!$A$5:$N$281,14,0)="","",VLOOKUP(A6,Summary_Index!$A$5:$N$281,14,0)),"")
A7: =Spatial!A7 -> 6 | B7: =Spatial!B7 -> Katunje_WSUC | C7: =Spatial!C7 -> Bagmati | D7: =Spatial!D7 -> Bhaktapur | E7: =Spatial!E7 -> Municipality | F7: =Spatial!F7 -> Suryabinayak | G7: =IFERROR(Spatial!G7,"") -> 0 | H7: 27.6654 | I7: 85.4195 | J7: =F7&"_"&D7 -> Suryabinayak_Bhaktapur | K7: =IFERROR(IF(VLOOKUP(A7,'Service Coverage'!$A:$C,3,0)="","",VLOOKUP(A7,'Service Coverage'!$A:$C,3,0)),"") | L7: =IFERROR(IF(VLOOKUP(A7,'Service Coverage'!$A:$D,4,0)="","",VLOOKUP(A7,'Service Coverage'!$A:$D,4,0)),"") -> 3360 | M7: =IFERROR(IF(VLOOKUP(A7,'Service Coverage'!$A:$E,5,0)="","",VLOOKUP(A7,'Service Coverage'!$A:$E,5,0)),"") | N7: =IFERROR(IF(VLOOKUP(A7,'Service Coverage'!$A:$F,6,0)="","",VLOOKUP(A7,'Service Coverage'!$A:$F,6,0)),"") | O7: =IFERROR(IF(VLOOKUP(A7,'Service Coverage'!$A:$G,7,0)="","",VLOOKUP(A7,'Service Coverage'!$A:$G,7,0)),"") | P7: =IFERROR(IF(VLOOKUP(A7,Adequacy!$A:$C,3,0)="","",VLOOKUP(A7,Adequacy!$A:$C,3,0)),"") | Q7: =IFERROR(IF(VLOOKUP(A7,Adequacy!$A:$D,4,0)="","",VLOOKUP(A7,Adequacy!$A:$D,4,0)),"") -> 2500 | R7: =IFERROR(IF(VLOOKUP(A7,Adequacy!$A:$E,5,0)="","",VLOOKUP(A7,Adequacy!$A:$E,5,0)),"") -> 19000 | S7: =IFERROR(IF(VLOOKUP(A7,Adequacy!$A:$G,7,0)="","",VLOOKUP(A7,Adequacy!$A:$G,7,0)),"") -> 4.3859649 | T7: =IFERROR(IF(VLOOKUP(A7,Adequacy!$A:$H,8,0)="","",VLOOKUP(A7,Adequacy!$A:$H,8,0)),"") | U7: =IFERROR(IF(VLOOKUP(A7,Adequacy!$A:$J,10,0)="","",VLOOKUP(A7,Adequacy!$A:$J,10,0)),"") | V7: =IFERROR(IF(VLOOKUP(A7,'Water Quality Score'!$A:$C,3,0)="","",VLOOKUP(A7,'Water Quality Score'!$A:$C,3,0)),"") -> yes | W7: =IFERROR(IF(VLOOKUP(A7,'Water Quality Score'!$A:$D,4,0)="","",VLOOKUP(A7,'Water Quality Score'!$A:$D,4,0)),"") | X7: =IFERROR(IF(VLOOKUP(A7,'Water Quality Score'!$A:$E,5,0)="","",VLOOKUP(A7,'Water Quality Score'!$A:$E,5,0)),"") | Y7: =IFERROR(IF(VLOOKUP(A7,'Water Quality Score'!$A:$F,6,0)="","",VLOOKUP(A7,'Water Quality Score'!$A:$F,6,0)),"") -> 0.2 | Z7: =IFERROR(IF(VLOOKUP(A7,'Reliability score'!$A:$C,3,0)="","",VLOOKUP(A7,'Reliability score'!$A:$C,3,0)),"") -> 4 | AA7: =IFERROR(IF(VLOOKUP(A7,'Reliability score'!$A:$D,4,0)="","",VLOOKUP(A7,'Reliability score'!$A:$D,4,0)),"") -> 0.52380952 | AB7: =IFERROR(IF(VLOOKUP(A7,NRW!$A:$C,3,0)="","",VLOOKUP(A7,NRW!$A:$C,3,0)),"") | AC7: =IFERROR(IF(VLOOKUP(A7,NRW!$A:$D,4,0)="","",VLOOKUP(A7,NRW!$A:$D,4,0)),"") | AD7: =IFERROR(IF(VLOOKUP(A7,NRW!$A:$E,5,0)="","",VLOOKUP(A7,NRW!$A:$E,5,0)),"") | AE7: =IFERROR(IF(VLOOKUP(A7,NRW!$A:$F,6,0)="","",VLOOKUP(A7,NRW!$A:$F,6,0)),"") | AF7: =IFERROR(IF(VLOOKUP(A7,NRW!$A:$G,7,0)="","",VLOOKUP(A7,NRW!$A:$G,7,0)),"") | AG7: =IFERROR(IF(OR(VLOOKUP(A7,NRW!$A:$H,8,0)="",VLOOKUP(A7,NRW!$A:$H,8,0)=0),"",VLOOKUP(A7,NRW!$A:$H,8,0)),"") | AH7: =IFERROR(IF(VLOOKUP(A7,'O&M score'!$A:$D,4,0)="","",VLOOKUP(A7,'O&M score'!$A:$D,4,0)),"") -> 875000 | AI7: =IFERROR(IF(VLOOKUP(A7,'O&M score'!$A:$E,5,0)="","",VLOOKUP(A7,'O&M score'!$A:$E,5,0)),"") -> 1700000 | AJ7: =IFERROR(IF(VLOOKUP(A7,'O&M score'!$A:$F,6,0)="","",VLOOKUP(A7,'O&M score'!$A:$F,6,0)),"") -> 0.51470588 | AK7: =IFERROR(IF(VLOOKUP(A7,'O&M score'!$A:$G,7,0)="","",VLOOKUP(A7,'O&M score'!$A:$G,7,0)),"") -> 1 | AL7: =IFERROR(IF(VLOOKUP(A7,'Metering Ratio Score'!$A:$C,3,0)="","",VLOOKUP(A7,'Metering Ratio Score'!$A:$C,3,0)),"") | AM7: =IFERROR(IF(VLOOKUP(A7,'Metering Ratio Score'!$A:$D,4,0)="","",VLOOKUP(A7,'Metering Ratio Score'!$A:$D,4,0)),"") | AN7: =IFERROR(IF(VLOOKUP(A7,'Metering Ratio Score'!$A:$E,5,0)="","",VLOOKUP(A7,'Metering Ratio Score'!$A:$E,5,0)),"") | AO7: =IFERROR(IF(VLOOKUP(A7,'Metering Ratio Score'!$A:$F,6,0)="","",VLOOKUP(A7,'Metering Ratio Score'!$A:$F,6,0)),"") | AP7: =IFERROR(IF(VLOOKUP(A7,'Grievance Addressal'!$A:$C,3,0)="","",VLOOKUP(A7,'Grievance Addressal'!$A:$C,3,0)),"") | AQ7: =IFERROR(IF(VLOOKUP(A7,'Grievance Addressal'!$A:$D,4,0)="","",VLOOKUP(A7,'Grievance Addressal'!$A:$D,4,0)),"") -> yes | AR7: =IFERROR(IF(VLOOKUP(A7,'Grievance Addressal'!$A:$E,5,0)="","",VLOOKUP(A7,'Grievance Addressal'!$A:$E,5,0)),"") | AS7: =IFERROR(IF(VLOOKUP(A7,Summary_Index!$A$5:$N$281,7,0)="","",VLOOKUP(A7,Summary_Index!$A$5:$N$281,7,0)),"") | AT7: =IFERROR(IF(VLOOKUP(A7,Summary_Index!$A$5:$N$281,12,0)="","",VLOOKUP(A7,Summary_Index!$A$5:$N$281,12,0)),"") | AU7: =IFERROR(IF(VLOOKUP(A7,Summary_Index!$A$5:$N$281,13,0)="","",VLOOKUP(A7,Summary_Index!$A$5:$N$281,13,0)),"") | AV7: =IFERROR(IF(VLOOKUP(A7,Summary_Index!$A$5:$N$281,14,0)="","",VLOOKUP(A7,Summary_Index!$A$5:$N$281,14,0)),"")
A8: =Spatial!A8 -> 7 | B8: =Spatial!B8 -> Nijgad_WSUC | C8: =Spatial!C8 -> Madhesh | D8: =Spatial!D8 -> Bara District | E8: =Spatial!E8 -> Municipality | F8: =Spatial!F8 -> Nijgad | G8: =IFERROR(Spatial!G8,"") -> 4,5,6,7,8,9 | H8: 27.0014 | I8: 85.1321 | J8: =F8&"_"&D8 -> Nijgad_Bara District | K8: =IFERROR(IF(VLOOKUP(A8,'Service Coverage'!$A:$C,3,0)="","",VLOOKUP(A8,'Service Coverage'!$A:$C,3,0)),"") | L8: =IFERROR(IF(VLOOKUP(A8,'Service Coverage'!$A:$D,4,0)="","",VLOOKUP(A8,'Service Coverage'!$A:$D,4,0)),"") | M8: =IFERROR(IF(VLOOKUP(A8,'Service Coverage'!$A:$E,5,0)="","",VLOOKUP(A8,'Service Coverage'!$A:$E,5,0)),"") | N8: =IFERROR(IF(VLOOKUP(A8,'Service Coverage'!$A:$F,6,0)="","",VLOOKUP(A8,'Service Coverage'!$A:$F,6,0)),"") | O8: =IFERROR(IF(VLOOKUP(A8,'Service Coverage'!$A:$G,7,0)="","",VLOOKUP(A8,'Service Coverage'!$A:$G,7,0)),"") | P8: =IFERROR(IF(VLOOKUP(A8,Adequacy!$A:$C,3,0)="","",VLOOKUP(A8,Adequacy!$A:$C,3,0)),"") | Q8: =IFERROR(IF(VLOOKUP(A8,Adequacy!$A:$D,4,0)="","",VLOOKUP(A8,Adequacy!$A:$D,4,0)),"") -> 2000 | R8: =IFERROR(IF(VLOOKUP(A8,Adequacy!$A:$E,5,0)="","",VLOOKUP(A8,Adequacy!$A:$E,5,0)),"") | S8: =IFERROR(IF(VLOOKUP(A8,Adequacy!$A:$G,7,0)="","",VLOOKUP(A8,Adequacy!$A:$G,7,0)),"") | T8: =IFERROR(IF(VLOOKUP(A8,Adequacy!$A:$H,8,0)="","",VLOOKUP(A8,Adequacy!$A:$H,8,0)),"") | U8: =IFERROR(IF(VLOOKUP(A8,Adequacy!$A:$J,10,0)="","",VLOOKUP(A8,Adequacy!$A:$J,10,0)),"") | V8: =IFERROR(IF(VLOOKUP(A8,'Water Quality Score'!$A:$C,3,0)="","",VLOOKUP(A8,'Water Quality Score'!$A:$C,3,0)),"") -> yes | W8: =IFERROR(IF(VLOOKUP(A8,'Water Quality Score'!$A:$D,4,0)="","",VLOOKUP(A8,'Water Quality Score'!$A:$D,4,0)),"") | X8: =IFERROR(IF(VLOOKUP(A8,'Water Quality Score'!$A:$E,5,0)="","",VLOOKUP(A8,'Water Quality Score'!$A:$E,5,0)),"") | Y8: =IFERROR(IF(VLOOKUP(A8,'Water Quality Score'!$A:$F,6,0)="","",VLOOKUP(A8,'Water Quality Score'!$A:$F,6,0)),"") -> 0.2 | Z8: =IFERROR(IF(VLOOKUP(A8,'Reliability score'!$A:$C,3,0)="","",VLOOKUP(A8,'Reliability score'!$A:$C,3,0)),"") -> 6 | AA8: =IFERROR(IF(VLOOKUP(A8,'Reliability score'!$A:$D,4,0)="","",VLOOKUP(A8,'Reliability score'!$A:$D,4,0)),"") -> 0.57142857 | AB8: =IFERROR(IF(VLOOKUP(A8,NRW!$A:$C,3,0)="","",VLOOKUP(A8,NRW!$A:$C,3,0)),"") | AC8: =IFERROR(IF(VLOOKUP(A8,NRW!$A:$D,4,0)="","",VLOOKUP(A8,NRW!$A:$D,4,0)),"") | AD8: =IFERROR(IF(VLOOKUP(A8,NRW!$A:$E,5,0)="","",VLOOKUP(A8,NRW!$A:$E,5,0)),"") | AE8: =IFERROR(IF(VLOOKUP(A8,NRW!$A:$F,6,0)="","",VLOOKUP(A8,NRW!$A:$F,6,0)),"") | AF8: =IFERROR(IF(VLOOKUP(A8,NRW!$A:$G,7,0)="","",VLOOKUP(A8,NRW!$A:$G,7,0)),"") | AG8: =IFERROR(IF(OR(VLOOKUP(A8,NRW!$A:$H,8,0)="",VLOOKUP(A8,NRW!$A:$H,8,0)=0),"",VLOOKUP(A8,NRW!$A:$H,8,0)),"") | AH8: =IFERROR(IF(VLOOKUP(A8,'O&M score'!$A:$D,4,0)="","",VLOOKUP(A8,'O&M score'!$A:$D,4,0)),"") | AI8: =IFERROR(IF(VLOOKUP(A8,'O&M score'!$A:$E,5,0)="","",VLOOKUP(A8,'O&M score'!$A:$E,5,0)),"") | AJ8: =IFERROR(IF(VLOOKUP(A8,'O&M score'!$A:$F,6,0)="","",VLOOKUP(A8,'O&M score'!$A:$F,6,0)),"") | AK8: =IFERROR(IF(VLOOKUP(A8,'O&M score'!$A:$G,7,0)="","",VLOOKUP(A8,'O&M score'!$A:$G,7,0)),"") | AL8: =IFERROR(IF(VLOOKUP(A8,'Metering Ratio Score'!$A:$C,3,0)="","",VLOOKUP(A8,'Metering Ratio Score'!$A:$C,3,0)),"") | AM8: =IFERROR(IF(VLOOKUP(A8,'Metering Ratio Score'!$A:$D,4,0)="","",VLOOKUP(A8,'Metering Ratio Score'!$A:$D,4,0)),"") | AN8: =IFERROR(IF(VLOOKUP(A8,'Metering Ratio Score'!$A:$E,5,0)="","",VLOOKUP(A8,'Metering Ratio Score'!$A:$E,5,0)),"") | AO8: =IFERROR(IF(VLOOKUP(A8,'Metering Ratio Score'!$A:$F,6,0)="","",VLOOKUP(A8,'Metering Ratio Score'!$A:$F,6,0)),"") | AP8: =IFERROR(IF(VLOOKUP(A8,'Grievance Addressal'!$A:$C,3,0)="","",VLOOKUP(A8,'Grievance Addressal'!$A:$C,3,0)),"") | AQ8: =IFERROR(IF(VLOOKUP(A8,'Grievance Addressal'!$A:$D,4,0)="","",VLOOKUP(A8,'Grievance Addressal'!$A:$D,4,0)),"") -> yes | AR8: =IFERROR(IF(VLOOKUP(A8,'Grievance Addressal'!$A:$E,5,0)="","",VLOOKUP(A8,'Grievance Addressal'!$A:$E,5,0)),"") | AS8: =IFERROR(IF(VLOOKUP(A8,Summary_Index!$A$5:$N$281,7,0)="","",VLOOKUP(A8,Summary_Index!$A$5:$N$281,7,0)),"") | AT8: =IFERROR(IF(VLOOKUP(A8,Summary_Index!$A$5:$N$281,12,0)="","",VLOOKUP(A8,Summary_Index!$A$5:$N$281,12,0)),"") | AU8: =IFERROR(IF(VLOOKUP(A8,Summary_Index!$A$5:$N$281,13,0)="","",VLOOKUP(A8,Summary_Index!$A$5:$N$281,13,0)),"") | AV8: =IFERROR(IF(VLOOKUP(A8,Summary_Index!$A$5:$N$281,14,0)="","",VLOOKUP(A8,Summary_Index!$A$5:$N$281,14,0)),"")
A9: =Spatial!A9 -> 8 | B9: =Spatial!B9 -> Tinthana_WSUC | C9: =Spatial!C9 -> Bagmati | D9: =Spatial!D9 -> Kathmandu District | E9: =Spatial!E9 -> Municipality | F9: =Spatial!F9 -> Chandragiri | G9: =IFERROR(Spatial!G9,"") -> 0 | H9: 27.6628 | I9: 85.2433 | J9: =F9&"_"&D9 -> Chandragiri_Kathmandu District | K9: =IFERROR(IF(VLOOKUP(A9,'Service Coverage'!$A:$C,3,0)="","",VLOOKUP(A9,'Service Coverage'!$A:$C,3,0)),"") | L9: =IFERROR(IF(VLOOKUP(A9,'Service Coverage'!$A:$D,4,0)="","",VLOOKUP(A9,'Service Coverage'!$A:$D,4,0)),"") -> 1979 | M9: =IFERROR(IF(VLOOKUP(A9,'Service Coverage'!$A:$E,5,0)="","",VLOOKUP(A9,'Service Coverage'!$A:$E,5,0)),"") | N9: =IFERROR(IF(VLOOKUP(A9,'Service Coverage'!$A:$F,6,0)="","",VLOOKUP(A9,'Service Coverage'!$A:$F,6,0)),"") | O9: =IFERROR(IF(VLOOKUP(A9,'Service Coverage'!$A:$G,7,0)="","",VLOOKUP(A9,'Service Coverage'!$A:$G,7,0)),"") | P9: =IFERROR(IF(VLOOKUP(A9,Adequacy!$A:$C,3,0)="","",VLOOKUP(A9,Adequacy!$A:$C,3,0)),"") | Q9: =IFERROR(IF(VLOOKUP(A9,Adequacy!$A:$D,4,0)="","",VLOOKUP(A9,Adequacy!$A:$D,4,0)),"") -> 1300 | R9: =IFERROR(IF(VLOOKUP(A9,Adequacy!$A:$E,5,0)="","",VLOOKUP(A9,Adequacy!$A:$E,5,0)),"") | S9: =IFERROR(IF(VLOOKUP(A9,Adequacy!$A:$G,7,0)="","",VLOOKUP(A9,Adequacy!$A:$G,7,0)),"") | T9: =IFERROR(IF(VLOOKUP(A9,Adequacy!$A:$H,8,0)="","",VLOOKUP(A9,Adequacy!$A:$H,8,0)),"") | U9: =IFERROR(IF(VLOOKUP(A9,Adequacy!$A:$J,10,0)="","",VLOOKUP(A9,Adequacy!$A:$J,10,0)),"") | V9: =IFERROR(IF(VLOOKUP(A9,'Water Quality Score'!$A:$C,3,0)="","",VLOOKUP(A9,'Water Quality Score'!$A:$C,3,0)),"") -> yes | W9: =IFERROR(IF(VLOOKUP(A9,'Water Quality Score'!$A:$D,4,0)="","",VLOOKUP(A9,'Water Quality Score'!$A:$D,4,0)),"") | X9: =IFERROR(IF(VLOOKUP(A9,'Water Quality Score'!$A:$E,5,0)="","",VLOOKUP(A9,'Water Quality Score'!$A:$E,5,0)),"") | Y9: =IFERROR(IF(VLOOKUP(A9,'Water Quality Score'!$A:$F,6,0)="","",VLOOKUP(A9,'Water Quality Score'!$A:$F,6,0)),"") -> 0.2 | Z9: =IFERROR(IF(VLOOKUP(A9,'Reliability score'!$A:$C,3,0)="","",VLOOKUP(A9,'Reliability score'!$A:$C,3,0)),"") | AA9: =IFERROR(IF(VLOOKUP(A9,'Reliability score'!$A:$D,4,0)="","",VLOOKUP(A9,'Reliability score'!$A:$D,4,0)),"") | AB9: =IFERROR(IF(VLOOKUP(A9,NRW!$A:$C,3,0)="","",VLOOKUP(A9,NRW!$A:$C,3,0)),"") | AC9: =IFERROR(IF(VLOOKUP(A9,NRW!$A:$D,4,0)="","",VLOOKUP(A9,NRW!$A:$D,4,0)),"") | AD9: =IFERROR(IF(VLOOKUP(A9,NRW!$A:$E,5,0)="","",VLOOKUP(A9,NRW!$A:$E,5,0)),"") | AE9: =IFERROR(IF(VLOOKUP(A9,NRW!$A:$F,6,0)="","",VLOOKUP(A9,NRW!$A:$F,6,0)),"") | AF9: =IFERROR(IF(VLOOKUP(A9,NRW!$A:$G,7,0)="","",VLOOKUP(A9,NRW!$A:$G,7,0)),"") | AG9: =IFERROR(IF(OR(VLOOKUP(A9,NRW!$A:$H,8,0)="",VLOOKUP(A9,NRW!$A:$H,8,0)=0),"",VLOOKUP(A9,NRW!$A:$H,8,0)),"") | AH9: =IFERROR(IF(VLOOKUP(A9,'O&M score'!$A:$D,4,0)="","",VLOOKUP(A9,'O&M score'!$A:$D,4,0)),"") | AI9: =IFERROR(IF(VLOOKUP(A9,'O&M score'!$A:$E,5,0)="","",VLOOKUP(A9,'O&M score'!$A:$E,5,0)),"") | AJ9: =IFERROR(IF(VLOOKUP(A9,'O&M score'!$A:$F,6,0)="","",VLOOKUP(A9,'O&M score'!$A:$F,6,0)),"") | AK9: =IFERROR(IF(VLOOKUP(A9,'O&M score'!$A:$G,7,0)="","",VLOOKUP(A9,'O&M score'!$A:$G,7,0)),"") | AL9: =IFERROR(IF(VLOOKUP(A9,'Metering Ratio Score'!$A:$C,3,0)="","",VLOOKUP(A9,'Metering Ratio Score'!$A:$C,3,0)),"") | AM9: =IFERROR(IF(VLOOKUP(A9,'Metering Ratio Score'!$A:$D,4,0)="","",VLOOKUP(A9,'Metering Ratio Score'!$A:$D,4,0)),"") | AN9: =IFERROR(IF(VLOOKUP(A9,'Metering Ratio Score'!$A:$E,5,0)="","",VLOOKUP(A9,'Metering Ratio Score'!$A:$E,5,0)),"") | AO9: =IFERROR(IF(VLOOKUP(A9,'Metering Ratio Score'!$A:$F,6,0)="","",VLOOKUP(A9,'Metering Ratio Score'!$A:$F,6,0)),"") | AP9: =IFERROR(IF(VLOOKUP(A9,'Grievance Addressal'!$A:$C,3,0)="","",VLOOKUP(A9,'Grievance Addressal'!$A:$C,3,0)),"") | AQ9: =IFERROR(IF(VLOOKUP(A9,'Grievance Addressal'!$A:$D,4,0)="","",VLOOKUP(A9,'Grievance Addressal'!$A:$D,4,0)),"") -> yes | AR9: =IFERROR(IF(VLOOKUP(A9,'Grievance Addressal'!$A:$E,5,0)="","",VLOOKUP(A9,'Grievance Addressal'!$A:$E,5,0)),"") | AS9: =IFERROR(IF(VLOOKUP(A9,Summary_Index!$A$5:$N$281,7,0)="","",VLOOKUP(A9,Summary_Index!$A$5:$N$281,7,0)),"") | AT9: =IFERROR(IF(VLOOKUP(A9,Summary_Index!$A$5:$N$281,12,0)="","",VLOOKUP(A9,Summary_Index!$A$5:$N$281,12,0)),"") | AU9: =IFERROR(IF(VLOOKUP(A9,Summary_Index!$A$5:$N$281,13,0)="","",VLOOKUP(A9,Summary_Index!$A$5:$N$281,13,0)),"") | AV9: =IFERROR(IF(VLOOKUP(A9,Summary_Index!$A$5:$N$281,14,0)="","",VLOOKUP(A9,Summary_Index!$A$5:$N$281,14,0)),"")
A10: =Spatial!A10 -> 9 | B10: =Spatial!B10 -> Birgunj_WSUC | C10: =Spatial!C10 -> Madhesh | D10: =Spatial!D10 -> Parsa District | E10: =Spatial!E10 -> Metropolitan | F10: =Spatial!F10 -> Birgunj | G10: =IFERROR(Spatial!G10,"") -> 1 ,2,3,4,5,6,7,8,9,10,11,12,13,14,15,16,17,18,19,20,21,22,23,24 | H10: 27.0104 | I10: 84.8772 | J10: =F10&"_"&D10 -> Birgunj_Parsa District | K10: =IFERROR(IF(VLOOKUP(A10,'Service Coverage'!$A:$C,3,0)="","",VLOOKUP(A10,'Service Coverage'!$A:$C,3,0)),"") | L10: =IFERROR(IF(VLOOKUP(A10,'Service Coverage'!$A:$D,4,0)="","",VLOOKUP(A10,'Service Coverage'!$A:$D,4,0)),"") | M10: =IFERROR(IF(VLOOKUP(A10,'Service Coverage'!$A:$E,5,0)="","",VLOOKUP(A10,'Service Coverage'!$A:$E,5,0)),"") | N10: =IFERROR(IF(VLOOKUP(A10,'Service Coverage'!$A:$F,6,0)="","",VLOOKUP(A10,'Service Coverage'!$A:$F,6,0)),"") | O10: =IFERROR(IF(VLOOKUP(A10,'Service Coverage'!$A:$G,7,0)="","",VLOOKUP(A10,'Service Coverage'!$A:$G,7,0)),"") | P10: =IFERROR(IF(VLOOKUP(A10,Adequacy!$A:$C,3,0)="","",VLOOKUP(A10,Adequacy!$A:$C,3,0)),"") | Q10: =IFERROR(IF(VLOOKUP(A10,Adequacy!$A:$D,4,0)="","",VLOOKUP(A10,Adequacy!$A:$D,4,0)),"") | R10: =IFERROR(IF(VLOOKUP(A10,Adequacy!$A:$E,5,0)="","",VLOOKUP(A10,Adequacy!$A:$E,5,0)),"") | S10: =IFERROR(IF(VLOOKUP(A10,Adequacy!$A:$G,7,0)="","",VLOOKUP(A10,Adequacy!$A:$G,7,0)),"") | T10: =IFERROR(IF(VLOOKUP(A10,Adequacy!$A:$H,8,0)="","",VLOOKUP(A10,Adequacy!$A:$H,8,0)),"") | U10: =IFERROR(IF(VLOOKUP(A10,Adequacy!$A:$J,10,0)="","",VLOOKUP(A10,Adequacy!$A:$J,10,0)),"") | V10: =IFERROR(IF(VLOOKUP(A10,'Water Quality Score'!$A:$C,3,0)="","",VLOOKUP(A10,'Water Quality Score'!$A:$C,3,0)),"") -> yes | W10: =IFERROR(IF(VLOOKUP(A10,'Water Quality Score'!$A:$D,4,0)="","",VLOOKUP(A10,'Water Quality Score'!$A:$D,4,0)),"") | X10: =IFERROR(IF(VLOOKUP(A10,'Water Quality Score'!$A:$E,5,0)="","",VLOOKUP(A10,'Water Quality Score'!$A:$E,5,0)),"") | Y10: =IFERROR(IF(VLOOKUP(A10,'Water Quality Score'!$A:$F,6,0)="","",VLOOKUP(A10,'Water Quality Score'!$A:$F,6,0)),"") -> 0.2 | Z10: =IFERROR(IF(VLOOKUP(A10,'Reliability score'!$A:$C,3,0)="","",VLOOKUP(A10,'Reliability score'!$A:$C,3,0)),"") -> 12 | AA10: =IFERROR(IF(VLOOKUP(A10,'Reliability score'!$A:$D,4,0)="","",VLOOKUP(A10,'Reliability score'!$A:$D,4,0)),"") -> 0.71428571 | AB10: =IFERROR(IF(VLOOKUP(A10,NRW!$A:$C,3,0)="","",VLOOKUP(A10,NRW!$A:$C,3,0)),"") | AC10: =IFERROR(IF(VLOOKUP(A10,NRW!$A:$D,4,0)="","",VLOOKUP(A10,NRW!$A:$D,4,0)),"") | AD10: =IFERROR(IF(VLOOKUP(A10,NRW!$A:$E,5,0)="","",VLOOKUP(A10,NRW!$A:$E,5,0)),"") | AE10: =IFERROR(IF(VLOOKUP(A10,NRW!$A:$F,6,0)="","",VLOOKUP(A10,NRW!$A:$F,6,0)),"") | AF10: =IFERROR(IF(VLOOKUP(A10,NRW!$A:$G,7,0)="","",VLOOKUP(A10,NRW!$A:$G,7,0)),"") | AG10: =IFERROR(IF(OR(VLOOKUP(A10,NRW!$A:$H,8,0)="",VLOOKUP(A10,NRW!$A:$H,8,0)=0),"",VLOOKUP(A10,NRW!$A:$H,8,0)),"") | AH10: =IFERROR(IF(VLOOKUP(A10,'O&M score'!$A:$D,4,0)="","",VLOOKUP(A10,'O&M score'!$A:$D,4,0)),"") | AI10: =IFERROR(IF(VLOOKUP(A10,'O&M score'!$A:$E,5,0)="","",VLOOKUP(A10,'O&M score'!$A:$E,5,0)),"") | AJ10: =IFERROR(IF(VLOOKUP(A10,'O&M score'!$A:$F,6,0)="","",VLOOKUP(A10,'O&M score'!$A:$F,6,0)),"") | AK10: =IFERROR(IF(VLOOKUP(A10,'O&M score'!$A:$G,7,0)="","",VLOOKUP(A10,'O&M score'!$A:$G,7,0)),"") | AL10: =IFERROR(IF(VLOOKUP(A10,'Metering Ratio Score'!$A:$C,3,0)="","",VLOOKUP(A10,'Metering Ratio Score'!$A:$C,3,0)),"") | AM10: =IFERROR(IF(VLOOKUP(A10,'Metering Ratio Score'!$A:$D,4,0)="","",VLOOKUP(A10,'Metering Ratio Score'!$A:$D,4,0)),"") | AN10: =IFERROR(IF(VLOOKUP(A10,'Metering Ratio Score'!$A:$E,5,0)="","",VLOOKUP(A10,'Metering Ratio Score'!$A:$E,5,0)),"") | AO10: =IFERROR(IF(VLOOKUP(A10,'Metering Ratio Score'!$A:$F,6,0)="","",VLOOKUP(A10,'Metering Ratio Score'!$A:$F,6,0)),"") | AP10: =IFERROR(IF(VLOOKUP(A10,'Grievance Addressal'!$A:$C,3,0)="","",VLOOKUP(A10,'Grievance Addressal'!$A:$C,3,0)),"") | AQ10: =IFERROR(IF(VLOOKUP(A10,'Grievance Addressal'!$A:$D,4,0)="","",VLOOKUP(A10,'Grievance Addressal'!$A:$D,4,0)),"") -> yes | AR10: =IFERROR(IF(VLOOKUP(A10,'Grievance Addressal'!$A:$E,5,0)="","",VLOOKUP(A10,'Grievance Addressal'!$A:$E,5,0)),"") | AS10: =IFERROR(IF(VLOOKUP(A10,Summary_Index!$A$5:$N$281,7,0)="","",VLOOKUP(A10,Summary_Index!$A$5:$N$281,7,0)),"") | AT10: =IFERROR(IF(VLOOKUP(A10,Summary_Index!$A$5:$N$281,12,0)="","",VLOOKUP(A10,Summary_Index!$A$5:$N$281,12,0)),"") | AU10: =IFERROR(IF(VLOOKUP(A10,Summary_Index!$A$5:$N$281,13,0)="","",VLOOKUP(A10,Summary_Index!$A$5:$N$281,13,0)),"") | AV10: =IFERROR(IF(VLOOKUP(A10,Summary_Index!$A$5:$N$281,14,0)="","",VLOOKUP(A10,Summary_Index!$A$5:$N$281,14,0)),"")
A11: =Spatial!A11 -> 10 | B11: =Spatial!B11 -> Gaur_WSUC | C11: =Spatial!C11 -> Madhesh | D11: =Spatial!D11 -> Rautahat District | E11: =Spatial!E11 -> Municipality | F11: =Spatial!F11 -> Gaur | G11: =IFERROR(Spatial!G11,"") -> 0 | H11: 26.7738 | I11: 85.2792 | J11: =F11&"_"&D11 -> Gaur_Rautahat District | K11: =IFERROR(IF(VLOOKUP(A11,'Service Coverage'!$A:$C,3,0)="","",VLOOKUP(A11,'Service Coverage'!$A:$C,3,0)),"") | L11: =IFERROR(IF(VLOOKUP(A11,'Service Coverage'!$A:$D,4,0)="","",VLOOKUP(A11,'Service Coverage'!$A:$D,4,0)),"") -> 1666 | M11: =IFERROR(IF(VLOOKUP(A11,'Service Coverage'!$A:$E,5,0)="","",VLOOKUP(A11,'Service Coverage'!$A:$E,5,0)),"") | N11: =IFERROR(IF(VLOOKUP(A11,'Service Coverage'!$A:$F,6,0)="","",VLOOKUP(A11,'Service Coverage'!$A:$F,6,0)),"") | O11: =IFERROR(IF(VLOOKUP(A11,'Service Coverage'!$A:$G,7,0)="","",VLOOKUP(A11,'Service Coverage'!$A:$G,7,0)),"") | P11: =IFERROR(IF(VLOOKUP(A11,Adequacy!$A:$C,3,0)="","",VLOOKUP(A11,Adequacy!$A:$C,3,0)),"") | Q11: =IFERROR(IF(VLOOKUP(A11,Adequacy!$A:$D,4,0)="","",VLOOKUP(A11,Adequacy!$A:$D,4,0)),"") -> 675 | R11: =IFERROR(IF(VLOOKUP(A11,Adequacy!$A:$E,5,0)="","",VLOOKUP(A11,Adequacy!$A:$E,5,0)),"") | S11: =IFERROR(IF(VLOOKUP(A11,Adequacy!$A:$G,7,0)="","",VLOOKUP(A11,Adequacy!$A:$G,7,0)),"") | T11: =IFERROR(IF(VLOOKUP(A11,Adequacy!$A:$H,8,0)="","",VLOOKUP(A11,Adequacy!$A:$H,8,0)),"") | U11: =IFERROR(IF(VLOOKUP(A11,Adequacy!$A:$J,10,0)="","",VLOOKUP(A11,Adequacy!$A:$J,10,0)),"") | V11: =IFERROR(IF(VLOOKUP(A11,'Water Quality Score'!$A:$C,3,0)="","",VLOOKUP(A11,'Water Quality Score'!$A:$C,3,0)),"") -> yes | W11: =IFERROR(IF(VLOOKUP(A11,'Water Quality Score'!$A:$D,4,0)="","",VLOOKUP(A11,'Water Quality Score'!$A:$D,4,0)),"") | X11: =IFERROR(IF(VLOOKUP(A11,'Water Quality Score'!$A:$E,5,0)="","",VLOOKUP(A11,'Water Quality Score'!$A:$E,5,0)),"") | Y11: =IFERROR(IF(VLOOKUP(A11,'Water Quality Score'!$A:$F,6,0)="","",VLOOKUP(A11,'Water Quality Score'!$A:$F,6,0)),"") -> 0.2 | Z11: =IFERROR(IF(VLOOKUP(A11,'Reliability score'!$A:$C,3,0)="","",VLOOKUP(A11,'Reliability score'!$A:$C,3,0)),"") -> 11 | AA11: =IFERROR(IF(VLOOKUP(A11,'Reliability score'!$A:$D,4,0)="","",VLOOKUP(A11,'Reliability score'!$A:$D,4,0)),"") -> 0.69047619 | AB11: =IFERROR(IF(VLOOKUP(A11,NRW!$A:$C,3,0)="","",VLOOKUP(A11,NRW!$A:$C,3,0)),"") | AC11: =IFERROR(IF(VLOOKUP(A11,NRW!$A:$D,4,0)="","",VLOOKUP(A11,NRW!$A:$D,4,0)),"") | AD11: =IFERROR(IF(VLOOKUP(A11,NRW!$A:$E,5,0)="","",VLOOKUP(A11,NRW!$A:$E,5,0)),"") | AE11: =IFERROR(IF(VLOOKUP(A11,NRW!$A:$F,6,0)="","",VLOOKUP(A11,NRW!$A:$F,6,0)),"") | AF11: =IFERROR(IF(VLOOKUP(A11,NRW!$A:$G,7,0)="","",VLOOKUP(A11,NRW!$A:$G,7,0)),"") | AG11: =IFERROR(IF(OR(VLOOKUP(A11,NRW!$A:$H,8,0)="",VLOOKUP(A11,NRW!$A:$H,8,0)=0),"",VLOOKUP(A11,NRW!$A:$H,8,0)),"") | AH11: =IFERROR(IF(VLOOKUP(A11,'O&M score'!$A:$D,4,0)="","",VLOOKUP(A11,'O&M score'!$A:$D,4,0)),"") | AI11: =IFERROR(IF(VLOOKUP(A11,'O&M score'!$A:$E,5,0)="","",VLOOKUP(A11,'O&M score'!$A:$E,5,0)),"") | AJ11: =IFERROR(IF(VLOOKUP(A11,'O&M score'!$A:$F,6,0)="","",VLOOKUP(A11,'O&M score'!$A:$F,6,0)),"") | AK11: =IFERROR(IF(VLOOKUP(A11,'O&M score'!$A:$G,7,0)="","",VLOOKUP(A11,'O&M score'!$A:$G,7,0)),"") | AL11: =IFERROR(IF(VLOOKUP(A11,'Metering Ratio Score'!$A:$C,3,0)="","",VLOOKUP(A11,'Metering Ratio Score'!$A:$C,3,0)),"") | AM11: =IFERROR(IF(VLOOKUP(A11,'Metering Ratio Score'!$A:$D,4,0)="","",VLOOKUP(A11,'Metering Ratio Score'!$A:$D,4,0)),"") | AN11: =IFERROR(IF(VLOOKUP(A11,'Metering Ratio Score'!$A:$E,5,0)="","",VLOOKUP(A11,'Metering Ratio Score'!$A:$E,5,0)),"") | AO11: =IFERROR(IF(VLOOKUP(A11,'Metering Ratio Score'!$A:$F,6,0)="","",VLOOKUP(A11,'Metering Ratio Score'!$A:$F,6,0)),"") | AP11: =IFERROR(IF(VLOOKUP(A11,'Grievance Addressal'!$A:$C,3,0)="","",VLOOKUP(A11,'Grievance Addressal'!$A:$C,3,0)),"") | AQ11: =IFERROR(IF(VLOOKUP(A11,'Grievance Addressal'!$A:$D,4,0)="","",VLOOKUP(A11,'Grievance Addressal'!$A:$D,4,0)),"") -> yes | AR11: =IFERROR(IF(VLOOKUP(A11,'Grievance Addressal'!$A:$E,5,0)="","",VLOOKUP(A11,'Grievance Addressal'!$A:$E,5,0)),"") | AS11: =IFERROR(IF(VLOOKUP(A11,Summary_Index!$A$5:$N$281,7,0)="","",VLOOKUP(A11,Summary_Index!$A$5:$N$281,7,0)),"") | AT11: =IFERROR(IF(VLOOKUP(A11,Summary_Index!$A$5:$N$281,12,0)="","",VLOOKUP(A11,Summary_Index!$A$5:$N$281,12,0)),"") | AU11: =IFERROR(IF(VLOOKUP(A11,Summary_Index!$A$5:$N$281,13,0)="","",VLOOKUP(A11,Summary_Index!$A$5:$N$281,13,0)),"") | AV11: =IFERROR(IF(VLOOKUP(A11,Summary_Index!$A$5:$N$281,14,0)="","",VLOOKUP(A11,Summary_Index!$A$5:$N$281,14,0)),"")
A12: =Spatial!A12 -> 11 | B12: =Spatial!B12 -> Beni_WSUC | C12: =Spatial!C12 -> Gandaki | D12: =Spatial!D12 -> Chitwan District | E12: =Spatial!E12 -> Municipality | F12: =Spatial!F12 -> Beni | G12: =IFERROR(Spatial!G12,"") -> 0 | H12: 28.35 | I12: 83.5833 | J12: =F12&"_"&D12 -> Beni_Chitwan District | K12: =IFERROR(IF(VLOOKUP(A12,'Service Coverage'!$A:$C,3,0)="","",VLOOKUP(A12,'Service Coverage'!$A:$C,3,0)),"") -> No | L12: =IFERROR(IF(VLOOKUP(A12,'Service Coverage'!$A:$D,4,0)="","",VLOOKUP(A12,'Service Coverage'!$A:$D,4,0)),"") -> 1143 | M12: =IFERROR(IF(VLOOKUP(A12,'Service Coverage'!$A:$E,5,0)="","",VLOOKUP(A12,'Service Coverage'!$A:$E,5,0)),"") | N12: =IFERROR(IF(VLOOKUP(A12,'Service Coverage'!$A:$F,6,0)="","",VLOOKUP(A12,'Service Coverage'!$A:$F,6,0)),"") | O12: =IFERROR(IF(VLOOKUP(A12,'Service Coverage'!$A:$G,7,0)="","",VLOOKUP(A12,'Service Coverage'!$A:$G,7,0)),"") | P12: =IFERROR(IF(VLOOKUP(A12,Adequacy!$A:$C,3,0)="","",VLOOKUP(A12,Adequacy!$A:$C,3,0)),"") | Q12: =IFERROR(IF(VLOOKUP(A12,Adequacy!$A:$D,4,0)="","",VLOOKUP(A12,Adequacy!$A:$D,4,0)),"") | R12: =IFERROR(IF(VLOOKUP(A12,Adequacy!$A:$E,5,0)="","",VLOOKUP(A12,Adequacy!$A:$E,5,0)),"") | S12: =IFERROR(IF(VLOOKUP(A12,Adequacy!$A:$G,7,0)="","",VLOOKUP(A12,Adequacy!$A:$G,7,0)),"") | T12: =IFERROR(IF(VLOOKUP(A12,Adequacy!$A:$H,8,0)="","",VLOOKUP(A12,Adequacy!$A:$H,8,0)),"") | U12: =IFERROR(IF(VLOOKUP(A12,Adequacy!$A:$J,10,0)="","",VLOOKUP(A12,Adequacy!$A:$J,10,0)),"") | V12: =IFERROR(IF(VLOOKUP(A12,'Water Quality Score'!$A:$C,3,0)="","",VLOOKUP(A12,'Water Quality Score'!$A:$C,3,0)),"") -> yes | W12: =IFERROR(IF(VLOOKUP(A12,'Water Quality Score'!$A:$D,4,0)="","",VLOOKUP(A12,'Water Quality Score'!$A:$D,4,0)),"") | X12: =IFERROR(IF(VLOOKUP(A12,'Water Quality Score'!$A:$E,5,0)="","",VLOOKUP(A12,'Water Quality Score'!$A:$E,5,0)),"") | Y12: =IFERROR(IF(VLOOKUP(A12,'Water Quality Score'!$A:$F,6,0)="","",VLOOKUP(A12,'Water Quality Score'!$A:$F,6,0)),"") -> 0.2 | Z12: =IFERROR(IF(VLOOKUP(A12,'Reliability score'!$A:$C,3,0)="","",VLOOKUP(A12,'Reliability score'!$A:$C,3,0)),"") | AA12: =IFERROR(IF(VLOOKUP(A12,'Reliability score'!$A:$D,4,0)="","",VLOOKUP(A12,'Reliability score'!$A:$D,4,0)),"") | AB12: =IFERROR(IF(VLOOKUP(A12,NRW!$A:$C,3,0)="","",VLOOKUP(A12,NRW!$A:$C,3,0)),"") | AC12: =IFERROR(IF(VLOOKUP(A12,NRW!$A:$D,4,0)="","",VLOOKUP(A12,NRW!$A:$D,4,0)),"") | AD12: =IFERROR(IF(VLOOKUP(A12,NRW!$A:$E,5,0)="","",VLOOKUP(A12,NRW!$A:$E,5,0)),"") | AE12: =IFERROR(IF(VLOOKUP(A12,NRW!$A:$F,6,0)="","",VLOOKUP(A12,NRW!$A:$F,6,0)),"") | AF12: =IFERROR(IF(VLOOKUP(A12,NRW!$A:$G,7,0)="","",VLOOKUP(A12,NRW!$A:$G,7,0)),"") | AG12: =IFERROR(IF(OR(VLOOKUP(A12,NRW!$A:$H,8,0)="",VLOOKUP(A12,NRW!$A:$H,8,0)=0),"",VLOOKUP(A12,NRW!$A:$H,8,0)),"") | AH12: =IFERROR(IF(VLOOKUP(A12,'O&M score'!$A:$D,4,0)="","",VLOOKUP(A12,'O&M score'!$A:$D,4,0)),"") | AI12: =IFERROR(IF(VLOOKUP(A12,'O&M score'!$A:$E,5,0)="","",VLOOKUP(A12,'O&M score'!$A:$E,5,0)),"") | AJ12: =IFERROR(IF(VLOOKUP(A12,'O&M score'!$A:$F,6,0)="","",VLOOKUP(A12,'O&M score'!$A:$F,6,0)),"") | AK12: =IFERROR(IF(VLOOKUP(A12,'O&M score'!$A:$G,7,0)="","",VLOOKUP(A12,'O&M score'!$A:$G,7,0)),"") | AL12: =IFERROR(IF(VLOOKUP(A12,'Metering Ratio Score'!$A:$C,3,0)="","",VLOOKUP(A12,'Metering Ratio Score'!$A:$C,3,0)),"") -> 1216 | AM12: =IFERROR(IF(VLOOKUP(A12,'Metering Ratio Score'!$A:$D,4,0)="","",VLOOKUP(A12,'Metering Ratio Score'!$A:$D,4,0)),"") | AN12: =IFERROR(IF(VLOOKUP(A12,'Metering Ratio Score'!$A:$E,5,0)="","",VLOOKUP(A12,'Metering Ratio Score'!$A:$E,5,0)),"") | AO12: =IFERROR(IF(VLOOKUP(A12,'Metering Ratio Score'!$A:$F,6,0)="","",VLOOKUP(A12,'Metering Ratio Score'!$A:$F,6,0)),"") | AP12: =IFERROR(IF(VLOOKUP(A12,'Grievance Addressal'!$A:$C,3,0)="","",VLOOKUP(A12,'Grievance Addressal'!$A:$C,3,0)),"") | AQ12: =IFERROR(IF(VLOOKUP(A12,'Grievance Addressal'!$A:$D,4,0)="","",VLOOKUP(A12,'Grievance Addressal'!$A:$D,4,0)),"") -> yes | AR12: =IFERROR(IF(VLOOKUP(A12,'Grievance Addressal'!$A:$E,5,0)="","",VLOOKUP(A12,'Grievance Addressal'!$A:$E,5,0)),"") | AS12: =IFERROR(IF(VLOOKUP(A12,Summary_Index!$A$5:$N$281,7,0)="","",VLOOKUP(A12,Summary_Index!$A$5:$N$281,7,0)),"") | AT12: =IFERROR(IF(VLOOKUP(A12,Summary_Index!$A$5:$N$281,12,0)="","",VLOOKUP(A12,Summary_Index!$A$5:$N$281,12,0)),"") | AU12: =IFERROR(IF(VLOOKUP(A12,Summary_Index!$A$5:$N$281,13,0)="","",VLOOKUP(A12,Summary_Index!$A$5:$N$281,13,0)),"") | AV12: =IFERROR(IF(VLOOKUP(A12,Summary_Index!$A$5:$N$281,14,0)="","",VLOOKUP(A12,Summary_Index!$A$5:$N$281,14,0)),"")
A13: =Spatial!A13 -> 12 | B13: =Spatial!B13 -> Narayansthan_WSUC | C13: =Spatial!C13 -> Gandaki | D13: =Spatial!D13 -> Chitwan District | E13: =Spatial!E13 -> Municipality | F13: =Spatial!F13 -> Baglung | G13: =IFERROR(Spatial!G13,"") -> 0 | H13: 28.2712 | I13: 83.5876 | J13: =F13&"_"&D13 -> Baglung_Chitwan District | K13: =IFERROR(IF(VLOOKUP(A13,'Service Coverage'!$A:$C,3,0)="","",VLOOKUP(A13,'Service Coverage'!$A:$C,3,0)),"") -> No | L13: =IFERROR(IF(VLOOKUP(A13,'Service Coverage'!$A:$D,4,0)="","",VLOOKUP(A13,'Service Coverage'!$A:$D,4,0)),"") -> 907 | M13: =IFERROR(IF(VLOOKUP(A13,'Service Coverage'!$A:$E,5,0)="","",VLOOKUP(A13,'Service Coverage'!$A:$E,5,0)),"") | N13: =IFERROR(IF(VLOOKUP(A13,'Service Coverage'!$A:$F,6,0)="","",VLOOKUP(A13,'Service Coverage'!$A:$F,6,0)),"") | O13: =IFERROR(IF(VLOOKUP(A13,'Service Coverage'!$A:$G,7,0)="","",VLOOKUP(A13,'Service Coverage'!$A:$G,7,0)),"") | P13: =IFERROR(IF(VLOOKUP(A13,Adequacy!$A:$C,3,0)="","",VLOOKUP(A13,Adequacy!$A:$C,3,0)),"") | Q13: =IFERROR(IF(VLOOKUP(A13,Adequacy!$A:$D,4,0)="","",VLOOKUP(A13,Adequacy!$A:$D,4,0)),"") | R13: =IFERROR(IF(VLOOKUP(A13,Adequacy!$A:$E,5,0)="","",VLOOKUP(A13,Adequacy!$A:$E,5,0)),"") | S13: =IFERROR(IF(VLOOKUP(A13,Adequacy!$A:$G,7,0)="","",VLOOKUP(A13,Adequacy!$A:$G,7,0)),"") | T13: =IFERROR(IF(VLOOKUP(A13,Adequacy!$A:$H,8,0)="","",VLOOKUP(A13,Adequacy!$A:$H,8,0)),"") | U13: =IFERROR(IF(VLOOKUP(A13,Adequacy!$A:$J,10,0)="","",VLOOKUP(A13,Adequacy!$A:$J,10,0)),"") | V13: =IFERROR(IF(VLOOKUP(A13,'Water Quality Score'!$A:$C,3,0)="","",VLOOKUP(A13,'Water Quality Score'!$A:$C,3,0)),"") -> Yes | W13: =IFERROR(IF(VLOOKUP(A13,'Water Quality Score'!$A:$D,4,0)="","",VLOOKUP(A13,'Water Quality Score'!$A:$D,4,0)),"") | X13: =IFERROR(IF(VLOOKUP(A13,'Water Quality Score'!$A:$E,5,0)="","",VLOOKUP(A13,'Water Quality Score'!$A:$E,5,0)),"") | Y13: =IFERROR(IF(VLOOKUP(A13,'Water Quality Score'!$A:$F,6,0)="","",VLOOKUP(A13,'Water Quality Score'!$A:$F,6,0)),"") -> 0.2 | Z13: =IFERROR(IF(VLOOKUP(A13,'Reliability score'!$A:$C,3,0)="","",VLOOKUP(A13,'Reliability score'!$A:$C,3,0)),"") | AA13: =IFERROR(IF(VLOOKUP(A13,'Reliability score'!$A:$D,4,0)="","",VLOOKUP(A13,'Reliability score'!$A:$D,4,0)),"") | AB13: =IFERROR(IF(VLOOKUP(A13,NRW!$A:$C,3,0)="","",VLOOKUP(A13,NRW!$A:$C,3,0)),"") | AC13: =IFERROR(IF(VLOOKUP(A13,NRW!$A:$D,4,0)="","",VLOOKUP(A13,NRW!$A:$D,4,0)),"") | AD13: =IFERROR(IF(VLOOKUP(A13,NRW!$A:$E,5,0)="","",VLOOKUP(A13,NRW!$A:$E,5,0)),"") | AE13: =IFERROR(IF(VLOOKUP(A13,NRW!$A:$F,6,0)="","",VLOOKUP(A13,NRW!$A:$F,6,0)),"") | AF13: =IFERROR(IF(VLOOKUP(A13,NRW!$A:$G,7,0)="","",VLOOKUP(A13,NRW!$A:$G,7,0)),"") | AG13: =IFERROR(IF(OR(VLOOKUP(A13,NRW!$A:$H,8,0)="",VLOOKUP(A13,NRW!$A:$H,8,0)=0),"",VLOOKUP(A13,NRW!$A:$H,8,0)),"") | AH13: =IFERROR(IF(VLOOKUP(A13,'O&M score'!$A:$D,4,0)="","",VLOOKUP(A13,'O&M score'!$A:$D,4,0)),"") -> 2373000 | AI13: =IFERROR(IF(VLOOKUP(A13,'O&M score'!$A:$E,5,0)="","",VLOOKUP(A13,'O&M score'!$A:$E,5,0)),"") -> 2468000 | AJ13: =IFERROR(IF(VLOOKUP(A13,'O&M score'!$A:$F,6,0)="","",VLOOKUP(A13,'O&M score'!$A:$F,6,0)),"") -> 0.96150729 | AK13: =IFERROR(IF(VLOOKUP(A13,'O&M score'!$A:$G,7,0)="","",VLOOKUP(A13,'O&M score'!$A:$G,7,0)),"") -> 0.47698541 | AL13: =IFERROR(IF(VLOOKUP(A13,'Metering Ratio Score'!$A:$C,3,0)="","",VLOOKUP(A13,'Metering Ratio Score'!$A:$C,3,0)),"") -> 907 | AM13: =IFERROR(IF(VLOOKUP(A13,'Metering Ratio Score'!$A:$D,4,0)="","",VLOOKUP(A13,'Metering Ratio Score'!$A:$D,4,0)),"") | AN13: =IFERROR(IF(VLOOKUP(A13,'Metering Ratio Score'!$A:$E,5,0)="","",VLOOKUP(A13,'Metering Ratio Score'!$A:$E,5,0)),"") | AO13: =IFERROR(IF(VLOOKUP(A13,'Metering Ratio Score'!$A:$F,6,0)="","",VLOOKUP(A13,'Metering Ratio Score'!$A:$F,6,0)),"") | AP13: =IFERROR(IF(VLOOKUP(A13,'Grievance Addressal'!$A:$C,3,0)="","",VLOOKUP(A13,'Grievance Addressal'!$A:$C,3,0)),"") | AQ13: =IFERROR(IF(VLOOKUP(A13,'Grievance Addressal'!$A:$D,4,0)="","",VLOOKUP(A13,'Grievance Addressal'!$A:$D,4,0)),"") -> yes | AR13: =IFERROR(IF(VLOOKUP(A13,'Grievance Addressal'!$A:$E,5,0)="","",VLOOKUP(A13,'Grievance Addressal'!$A:$E,5,0)),"") | AS13: =IFERROR(IF(VLOOKUP(A13,Summary_Index!$A$5:$N$281,7,0)="","",VLOOKUP(A13,Summary_Index!$A$5:$N$281,7,0)),"") | AT13: =IFERROR(IF(VLOOKUP(A13,Summary_Index!$A$5:$N$281,12,0)="","",VLOOKUP(A13,Summary_Index!$A$5:$N$281,12,0)),"") | AU13: =IFERROR(IF(VLOOKUP(A13,Summary_Index!$A$5:$N$281,13,0)="","",VLOOKUP(A13,Summary_Index!$A$5:$N$281,13,0)),"") | AV13: =IFERROR(IF(VLOOKUP(A13,Summary_Index!$A$5:$N$281,14,0)="","",VLOOKUP(A13,Summary_Index!$A$5:$N$281,14,0)),"")
... A35: =Spatial!A35 -> 34 | B35: =Spatial!B35 -> Ghorahi_WSUC | C35: =Spatial!C35 -> 0 | D35: =Spatial!D35 -> 0 | E35: =Spatial!E35 -> Municipality | F35: =Spatial!F35 -> Dang | G35: =IFERROR(Spatial!G35,"") -> 0 | H35: 28.0333 | I35: 82.4833 | J35: =F35&"_"&D35 -> Dang_0 | K35: =IFERROR(IF(VLOOKUP(A35,'Service Coverage'!$A:$C,3,0)="","",VLOOKUP(A35,'Service Coverage'!$A:$C,3,0)),"") -> No | L35: =IFERROR(IF(VLOOKUP(A35,'Service Coverage'!$A:$D,4,0)="","",VLOOKUP(A35,'Service Coverage'!$A:$D,4,0)),"") -> 8385 | M35: =IFERROR(IF(VLOOKUP(A35,'Service Coverage'!$A:$E,5,0)="","",VLOOKUP(A35,'Service Coverage'!$A:$E,5,0)),"") | N35: =IFERROR(IF(VLOOKUP(A35,'Service Coverage'!$A:$F,6,0)="","",VLOOKUP(A35,'Service Coverage'!$A:$F,6,0)),"") | O35: =IFERROR(IF(VLOOKUP(A35,'Service Coverage'!$A:$G,7,0)="","",VLOOKUP(A35,'Service Coverage'!$A:$G,7,0)),"") | P35: =IFERROR(IF(VLOOKUP(A35,Adequacy!$A:$C,3,0)="","",VLOOKUP(A35,Adequacy!$A:$C,3,0)),"") | Q35: =IFERROR(IF(VLOOKUP(A35,Adequacy!$A:$D,4,0)="","",VLOOKUP(A35,Adequacy!$A:$D,4,0)),"") | R35: =IFERROR(IF(VLOOKUP(A35,Adequacy!$A:$E,5,0)="","",VLOOKUP(A35,Adequacy!$A:$E,5,0)),"") | S35: =IFERROR(IF(VLOOKUP(A35,Adequacy!$A:$G,7,0)="","",VLOOKUP(A35,Adequacy!$A:$G,7,0)),"") | T35: =IFERROR(IF(VLOOKUP(A35,Adequacy!$A:$H,8,0)="","",VLOOKUP(A35,Adequacy!$A:$H,8,0)),"") | U35: =IFERROR(IF(VLOOKUP(A35,Adequacy!$A:$J,10,0)="","",VLOOKUP(A35,Adequacy!$A:$J,10,0)),"") | V35: =IFERROR(IF(VLOOKUP(A35,'Water Quality Score'!$A:$C,3,0)="","",VLOOKUP(A35,'Water Quality Score'!$A:$C,3,0)),"") -> yes | W35: =IFERROR(IF(VLOOKUP(A35,'Water Quality Score'!$A:$D,4,0)="","",VLOOKUP(A35,'Water Quality Score'!$A:$D,4,0)),"") | X35: =IFERROR(IF(VLOOKUP(A35,'Water Quality Score'!$A:$E,5,0)="","",VLOOKUP(A35,'Water Quality Score'!$A:$E,5,0)),"") | Y35: =IFERROR(IF(VLOOKUP(A35,'Water Quality Score'!$A:$F,6,0)="","",VLOOKUP(A35,'Water Quality Score'!$A:$F,6,0)),"") -> 0.2 | Z35: =IFERROR(IF(VLOOKUP(A35,'Reliability score'!$A:$C,3,0)="","",VLOOKUP(A35,'Reliability score'!$A:$C,3,0)),"") | AA35: =IFERROR(IF(VLOOKUP(A35,'Reliability score'!$A:$D,4,0)="","",VLOOKUP(A35,'Reliability score'!$A:$D,4,0)),"") | AB35: =IFERROR(IF(VLOOKUP(A35,NRW!$A:$C,3,0)="","",VLOOKUP(A35,NRW!$A:$C,3,0)),"") | AC35: =IFERROR(IF(VLOOKUP(A35,NRW!$A:$D,4,0)="","",VLOOKUP(A35,NRW!$A:$D,4,0)),"") | AD35: =IFERROR(IF(VLOOKUP(A35,NRW!$A:$E,5,0)="","",VLOOKUP(A35,NRW!$A:$E,5,0)),"") | AE35: =IFERROR(IF(VLOOKUP(A35,NRW!$A:$F,6,0)="","",VLOOKUP(A35,NRW!$A:$F,6,0)),"") | AF35: =IFERROR(IF(VLOOKUP(A35,NRW!$A:$G,7,0)="","",VLOOKUP(A35,NRW!$A:$G,7,0)),"") | AG35: =IFERROR(IF(OR(VLOOKUP(A35,NRW!$A:$H,8,0)="",VLOOKUP(A35,NRW!$A:$H,8,0)=0),"",VLOOKUP(A35,NRW!$A:$H,8,0)),"") | AH35: =IFERROR(IF(VLOOKUP(A35,'O&M score'!$A:$D,4,0)="","",VLOOKUP(A35,'O&M score'!$A:$D,4,0)),"") | AI35: =IFERROR(IF(VLOOKUP(A35,'O&M score'!$A:$E,5,0)="","",VLOOKUP(A35,'O&M score'!$A:$E,5,0)),"") | AJ35: =IFERROR(IF(VLOOKUP(A35,'O&M score'!$A:$F,6,0)="","",VLOOKUP(A35,'O&M score'!$A:$F,6,0)),"") | AK35: =IFERROR(IF(VLOOKUP(A35,'O&M score'!$A:$G,7,0)="","",VLOOKUP(A35,'O&M score'!$A:$G,7,0)),"") | AL35: =IFERROR(IF(VLOOKUP(A35,'Metering Ratio Score'!$A:$C,3,0)="","",VLOOKUP(A35,'Metering Ratio Score'!$A:$C,3,0)),"") -> 8300 | AM35: =IFERROR(IF(VLOOKUP(A35,'Metering Ratio Score'!$A:$D,4,0)="","",VLOOKUP(A35,'Metering Ratio Score'!$A:$D,4,0)),"") | AN35: =IFERROR(IF(VLOOKUP(A35,'Metering Ratio Score'!$A:$E,5,0)="","",VLOOKUP(A35,'Metering Ratio Score'!$A:$E,5,0)),"") | AO35: =IFERROR(IF(VLOOKUP(A35,'Metering Ratio Score'!$A:$F,6,0)="","",VLOOKUP(A35,'Metering Ratio Score'!$A:$F,6,0)),"") | AP35: =IFERROR(IF(VLOOKUP(A35,'Grievance Addressal'!$A:$C,3,0)="","",VLOOKUP(A35,'Grievance Addressal'!$A:$C,3,0)),"") | AQ35: =IFERROR(IF(VLOOKUP(A35,'Grievance Addressal'!$A:$D,4,0)="","",VLOOKUP(A35,'Grievance Addressal'!$A:$D,4,0)),"") -> yes | AR35: =IFERROR(IF(VLOOKUP(A35,'Grievance Addressal'!$A:$E,5,0)="","",VLOOKUP(A35,'Grievance Addressal'!$A:$E,5,0)),"") | AS35: =IFERROR(IF(VLOOKUP(A35,Summary_Index!$A$5:$N$281,7,0)="","",VLOOKUP(A35,Summary_Index!$A$5:$N$281,7,0)),"") | AT35: =IFERROR(IF(VLOOKUP(A35,Summary_Index!$A$5:$N$281,12,0)="","",VLOOKUP(A35,Summary_Index!$A$5:$N$281,12,0)),"") | AU35: =IFERROR(IF(VLOOKUP(A35,Summary_Index!$A$5:$N$281,13,0)="","",VLOOKUP(A35,Summary_Index!$A$5:$N$281,13,0)),"") | AV35: =IFERROR(IF(VLOOKUP(A35,Summary_Index!$A$5:$N$281,14,0)="","",VLOOKUP(A35,Summary_Index!$A$5:$N$281,14,0)),"")
